Workbook

Sheet Planilha1
B2: ATULAIZAÇÃO DE INVENTÁRIO EPPs - DEMAIS EQUIPAMENTOS
A5: EPB | B5: FAMÍLIA | C5: SUB-FAMÍLIAS | O5: TOTAIS | V5: OBSERVAÇÕES | AD5: Avanço 24 | AE5: Avanço 25
C6: Até 1988 | G6: Após 1988 | K6: Sem Info. | AD6: {=(SUM((IF(I8:I12<=H8:H12,I8:I12,H8:H12)),(IF(E8:E12<=D8:D12,E8:E12,D8:D12)),(IF(M8:M12<=L8:L12,M8:M12,L8:L12))))/P13} -> 0.32758621 | AE6: {=IF(AD6>=1,"N/A",SUM((IF((E8:E12+F8:F12)>D8:D12,ABS(D8:D12-E8:E12),F8:F12)),(IF((I8:I12+J8:J12)>H8:H12,ABS(H8:H12-I8:I12),J8:J12)),(IF((M8:M12+N8:N12)>L8:L12,ABS(L8:L12-M8:M12),N8:N12)))/(P13-Q13))} -> 1 | AI6: =AVERAGE(AE6,AE17,AE39,AE50,AE61,AE72,AE83) -> 0.52477388
C7: Previsto | D7: Atualiz. | E7: Real. 24 | F7: Real. 25 | G7: Previsto | H7: Atualiz. | I7: Real. 24 | J7: Real. 25 | K7: Previsto | L7: Atualiz. | M7: Real. 24 | N7: Real. 25 | O7: Previstos | P7: Atualiz. | Q7: Real. 24 | R7: Real. 25 | S7: T. Consid. | T7: Fal. Teste | U7: Avanço | V7: O número do inventário foi alterado para 343. Estamos aguardando a EPB identificar de que família foi abatido.
B8: Transformador de rede subterrânea | C8: 0 | D8: 0 | G8: 0 | H8: 0 | K8: 0 | L8: 0 | O8: =SUM(C8,G8,K8) -> 0 | P8: =SUM(D8,H8,L8) -> 0 | Q8: =IF(P8=0,"-",SUM(E8,I8,M8)) -> - | R8: =IF(P8=0,"-",SUM(F8,J8,N8)) -> - | S8: =IF(P8=0,"-",SUM((IF((E8+F8)>228,D8,IF((E8+F8)>D8,D8,(E8+F8)))),IF((I8+J8)>228,H8,IF((I8+J8)>H8,H8,(I8+J8))),(IF((M8+N8)>228,L8,IF((M8+N8)>L8,L8,(M8+N8)))))) -> - | T8: =IF(P8=0,"-",(P8-S8)) -> - | U8: =IF(P8=0,"-",(1-(T8/P8))) -> -
B9: Disjuntores com extinção de arco em OMI (PVO e GVO) | C9: 0 | D9: 0 | G9: 0 | H9: 0 | K9: 0 | L9: 0 | O9: =SUM(C9,G9,K9) -> 0 | P9: =SUM(D9,H9,L9) -> 0 | Q9: =IF(P9=0,"-",SUM(E9,I9,M9)) -> - | R9: =IF(P9=0,"-",SUM(F9,J9,N9)) -> - | S9: =IF(P9=0,"-",SUM((IF((E9+F9)>228,D9,IF((E9+F9)>D9,D9,(E9+F9)))),IF((I9+J9)>228,H9,IF((I9+J9)>H9,H9,(I9+J9))),(IF((M9+N9)>228,L9,IF((M9+N9)>L9,L9,(M9+N9)))))) -> - | T9: =IF(P9=0,"-",(P9-S9)) -> - | U9: =IF(P9=0,"-",(1-(T9/P9))) -> -
B10: Religadores | C10: 0 | D10: 0 | G10: 46 | H10: 22 | J10: 22 | K10: 0 | L10: 0 | O10: =SUM(C10,G10,K10) -> 46 | P10: =SUM(D10,H10,L10) -> 22 | Q10: =IF(P10=0,"-",SUM(E10,I10,M10)) -> 0 | R10: =IF(P10=0,"-",SUM(F10,J10,N10)) -> 22 | S10: =IF(P10=0,"-",SUM((IF((E10+F10)>228,D10,IF((E10+F10)>D10,D10,(E10+F10)))),IF((I10+J10)>228,H10,IF((I10+J10)>H10,H10,(I10+J10))),(IF((M10+N10)>228,L10,IF((M10+N10)>L10,L10,(M10+N10)))))) -> 22 | T10: =IF(P10=0,"-",(P10-S10)) -> 0 | U10: =IF(P10=0,"-",(1-(T10/P10))) -> 1
B11: Reguladores de tensão de rede | C11: 6 | D11: 0 | G11: 228 | H11: 228 | I11: 95 | J11: =(114+116) -> 230 | K11: 228 | L11: 0 | N11: =(5+2) -> 7 | O11: =SUM(C11,G11,K11) -> 462 | P11: =SUM(D11,H11,L11) -> 228 | Q11: =IF(P11=0,"-",SUM(E11,I11,M11)) -> 95 | R11: =IF(P11=0,"-",SUM(F11,J11,N11)) -> 237 | S11: =IF(P11=0,"-",SUM((IF((E11+F11)>228,D11,IF((E11+F11)>D11,D11,(E11+F11)))),IF((I11+J11)>228,H11,IF((I11+J11)>H11,H11,(I11+J11))),(IF((M11+N11)>228,L11,IF((M11+N11)>L11,L11,(M11+N11)))))) -> 228 | T11: =IF(P11=0,"-",(P11-S11)) -> 0 | U11: =IF(P11=0,"-",(1-(T11/P11))) -> 1
B12: Outros equipamentos de pequeno porte e/ou rede | C12: 7 | D12: 9 | E12: 1 | F12: 8 | G12: 83 | H12: 87 | I12: 18 | J12: 69 | K12: 4 | L12: 2 | N12: 4 | O12: =SUM(C12,G12,K12) -> 94 | P12: =SUM(D12,H12,L12) -> 98 | Q12: =IF(P12=0,"-",SUM(E12,I12,M12)) -> 19 | R12: =IF(P12=0,"-",SUM(F12,J12,N12)) -> 81 | S12: =IF(P12=0,"-",SUM((IF((E12+F12)>228,D12,IF((E12+F12)>D12,D12,(E12+F12)))),IF((I12+J12)>228,H12,IF((I12+J12)>H12,H12,(I12+J12))),(IF((M12+N12)>228,L12,IF((M12+N12)>L12,L12,(M12+N12)))))) -> 98 | T12: =IF(P12=0,"-",(P12-S12)) -> 0 | U12: =IF(P12=0,"-",(1-(T12/P12))) -> 1
B13: TOTAIS | C13: =SUM(C8:C12) -> 13 | D13: =SUM(D8:D12) -> 9 | E13: =SUM(E8:E12) -> 1 | F13: =SUM(F8:F12) -> 8 | G13: =SUM(G8:G12) -> 357 | H13: =SUM(H8:H12) -> 337 | I13: =SUM(I8:I12) -> 113 | J13: =SUM(J8:J12) -> 321 | ... S13: =SUM(S8:S12) -> 348 | T13: =(P13-S13) -> 0 | U13: =IF(P13=0,"-",(1-(T13/P13))) -> 1
A16: ESE | B16: FAMÍLIA | C16: SUB-FAMÍLIAS | O16: TOTAIS | V16: OBSERVAÇÕES | AD16: Avanço 24 | AE16: Avanço 25
C17: Até 1988 | G17: Após 1988 | K17: Sem Info. | AD17: {=(SUM((IF(I19:I23<=H19:H23,I19:I23,H19:H23)),(IF(E19:E23<=D19:D23,E19:E23,D19:D23)),(IF(M19:M23<=L19:L23,M19:M23,L19:L23))))/P24} -> 0.28571429 | AE17: {=SUM((IF((E19:E23+F19:F23)>D19:D23,ABS(D19:D23-E19:E23),F19:F23)),(IF((I19:I23+J19:J23)>H19:H23,ABS(H19:H23-I19:I23),J19:J23)),(IF((M19:M23+N19:N23)>L19:L23,ABS(L19:L23-M19:M23),N19:N23)))/(P24-Q24)} -> 0
C18: Previsto | D18: Atualiz. | E18: Real. 24 | F18: Real. 25 | G18: Previsto | H18: Atualiz. | I18: Real. 24 | J18: Real. 25 | K18: Previsto | L18: Atualiz. | M18: Real. 24 | N18: Real. 25 | O18: Previstos | P18: Atualiz. | Q18: Real. 24 | R18: Real. 25 | S18: T. Consid. | T18: Fal. Teste | U18: Avanço | V18: 1 - o Marlon da informou que não existe na base de ativos da empresa RT sem informação de data. Foi solicitado que o mesmo enviasse descritivo nos informando o nmero a considerar. 2 - Foi informado que todos os Religadores instalados no parque são a vácuo e não existe em sua base equipamentos a óleo.
B19: Transformador de rede subterrânea | G19: 22 | H19: 0 | K19: 6 | L19: 6 | O19: =SUM(C19,G19,K19) -> 28 | P19: =SUM(D19,H19,L19) -> 6 | Q19: =IF(P19=0,"-",SUM(E19,I19,M19)) -> 0 | R19: =IF(P19=0,"-",SUM(F19,J19,N19)) -> 0 | S19: =IF(P19=0,"-",SUM((IF((E19+F19)>228,D19,IF((E19+F19)>D19,D19,(E19+F19)))),IF((I19+J19)>228,H19,IF((I19+J19)>H19,H19,(I19+J19))),(IF((M19+N19)>228,L19,IF((M19+N19)>L19,L19,(M19+N19)))))) -> 0 | T19: =IF(P19=0,"-",(P19-S19)) -> 6 | U19: =IF(P19=0,"-",(1-(T19/P19))) -> 0
B20: Disjuntores com extinção de arco em OMI (PVO e GVO) | C20: 1 | D20: 1 | G20: 6 | O20: =SUM(C20,G20,K20) -> 7 | P20: =SUM(D20,H20,L20) -> 1 | Q20: =IF(P20=0,"-",SUM(E20,I20,M20)) -> 0 | R20: =IF(P20=0,"-",SUM(F20,J20,N20)) -> 0 | S20: =IF(P20=0,"-",SUM((IF((E20+F20)>228,D20,IF((E20+F20)>D20,D20,(E20+F20)))),IF((I20+J20)>228,H20,IF((I20+J20)>H20,H20,(I20+J20))),(IF((M20+N20)>228,L20,IF((M20+N20)>L20,L20,(M20+N20)))))) -> 0 | T20: =IF(P20=0,"-",(P20-S20)) -> 1 | U20: =IF(P20=0,"-",(1-(T20/P20))) -> 0
B21: Religadores | G21: 121 | H21: 0 | K21: 55 | L21: 0 | O21: =SUM(C21,G21,K21) -> 176 | P21: =SUM(D21,H21,L21) -> 0 | Q21: =IF(P21=0,"-",SUM(E21,I21,M21)) -> - | R21: =IF(P21=0,"-",SUM(F21,J21,N21)) -> - | S21: =IF(P21=0,"-",SUM((IF((E21+F21)>228,D21,IF((E21+F21)>D21,D21,(E21+F21)))),IF((I21+J21)>228,H21,IF((I21+J21)>H21,H21,(I21+J21))),(IF((M21+N21)>228,L21,IF((M21+N21)>L21,L21,(M21+N21)))))) -> - | T21: =IF(P21=0,"-",(P21-S21)) -> - | U21: =IF(P21=0,"-",(1-(T21/P21))) -> -
B22: Reguladores de tensão de rede | G22: 179 | H22: 179 | I22: 120 | K22: 113 | L22: 113 | O22: =SUM(C22,G22,K22) -> 292 | P22: =SUM(D22,H22,L22) -> 292 | Q22: =IF(P22=0,"-",SUM(E22,I22,M22)) -> 120 | R22: =IF(P22=0,"-",SUM(F22,J22,N22)) -> 0 | S22: =IF(P22=0,"-",SUM((IF((E22+F22)>228,D22,IF((E22+F22)>D22,D22,(E22+F22)))),IF((I22+J22)>228,H22,IF((I22+J22)>H22,H22,(I22+J22))),(IF((M22+N22)>228,L22,IF((M22+N22)>L22,L22,(M22+N22)))))) -> 120 | T22: =IF(P22=0,"-",(P22-S22)) -> 172 | U22: =IF(P22=0,"-",(1-(T22/P22))) -> 0.4109589
B23: Outros equipamentos de pequeno porte e/ou rede | C23: 12 | D23: 12 | G23: 110 | K23: 109 | L23: 109 | O23: =SUM(C23,G23,K23) -> 231 | P23: =SUM(D23,H23,L23) -> 121 | Q23: =IF(P23=0,"-",SUM(E23,I23,M23)) -> 0 | R23: =IF(P23=0,"-",SUM(F23,J23,N23)) -> 0 | S23: =IF(P23=0,"-",SUM((IF((E23+F23)>228,D23,IF((E23+F23)>D23,D23,(E23+F23)))),IF((I23+J23)>228,H23,IF((I23+J23)>H23,H23,(I23+J23))),(IF((M23+N23)>228,L23,IF((M23+N23)>L23,L23,(M23+N23)))))) -> 0 | T23: =IF(P23=0,"-",(P23-S23)) -> 121 | U23: =IF(P23=0,"-",(1-(T23/P23))) -> 0
B24: TOTAIS | C24: =SUM(C19:C23) -> 13 | D24: =SUM(D19:D23) -> 13 | E24: =SUM(E19:E23) -> 0 | F24: =SUM(F19:F23) -> 0 | G24: =SUM(G19:G23) -> 438 | H24: =SUM(H19:H23) -> 179 | I24: =SUM(I19:I23) -> 120 | J24: =SUM(J19:J23) -> 0 | ... S24: =SUM(S19:S23) -> 120 | T24: =(P24-S24) -> 300 | U24: =IF(P24=0,"-",(1-(T24/P24))) -> 0.28571429
A27: EMR | B27: FAMÍLIA | C27: SUB-FAMÍLIAS | O27: TOTAIS | V27: OBSERVAÇÕES | AD27: Avanço 24 | AE27: Avanço 25
C28: Até 1988 | G28: Após 1988 | K28: Sem Info. | AD28: {=(SUM((IF(I30:I34<=H30:H34,I30:I34,H30:H34)),(IF(E30:E34<=D30:D34,E30:E34,D30:D34)),(IF(M30:M34<=L30:L34,M30:M34,L30:L34))))/P35} -> 1 | AE28: {=IF(AD28>=1,"N/A",SUM((IF((E30:E34+F30:F34)>D30:D34,ABS(D30:D34-E30:E34),F30:F34)),(IF((I30:I34+J30:J34)>H30:H34,ABS(H30:H34-I30:I34),J30:J34)),(IF((M30:M34+N30:N34)>L30:L34,ABS(L30:L34-M30:M34),N30:N34)))/(P35-Q35))} -> N/A
C29: Previsto | D29: Atualiz. | E29: Real. 24 | F29: Real. 25 | G29: Previsto | H29: Atualiz. | I29: Real. 24 | J29: Real. 25 | K29: Previsto | L29: Atualiz. | M29: Real. 24 | N29: Real. 25 | O29: Previstos | P29: Atualiz. | Q29: Real. 24 | R29: Real. 25 | S29: T. Consid. | T29: Fal. Teste | U29: Avanço
B30: Transformador de rede subterrânea | O30: =SUM(C30,G30,K30) -> 0 | P30: =SUM(D30,H30,L30) -> 0 | Q30: =IF(P30=0,"-",SUM(E30,I30,M30)) -> - | R30: =IF(P30=0,"-",SUM(F30,J30,N30)) -> - | S30: =IF(P30=0,"-",SUM((IF((E30+F30)>228,D30,IF((E30+F30)>D30,D30,(E30+F30)))),IF((I30+J30)>228,H30,IF((I30+J30)>H30,H30,(I30+J30))),(IF((M30+N30)>228,L30,IF((M30+N30)>L30,L30,(M30+N30)))))) -> - | T30: =IF(P30=0,"-",(P30-S30)) -> - | U30: =IF(P30=0,"-",(1-(T30/P30))) -> -
B31: Disjuntores com extinção de arco em OMI (PVO e GVO) | C31: 15 | D31: 15 | E31: 15 | G31: 14 | H31: 14 | I31: 14 | O31: =SUM(C31,G31,K31) -> 29 | P31: =SUM(D31,H31,L31) -> 29 | Q31: =IF(P31=0,"-",SUM(E31,I31,M31)) -> 29 | R31: =IF(P31=0,"-",SUM(F31,J31,N31)) -> 0 | S31: =IF(P31=0,"-",SUM((IF((E31+F31)>228,D31,IF((E31+F31)>D31,D31,(E31+F31)))),IF((I31+J31)>228,H31,IF((I31+J31)>H31,H31,(I31+J31))),(IF((M31+N31)>228,L31,IF((M31+N31)>L31,L31,(M31+N31)))))) -> 29 | T31: =IF(P31=0,"-",(P31-S31)) -> 0 | U31: =IF(P31=0,"-",(1-(T31/P31))) -> 1
B32: Religadores | G32: 18 | H32: 18 | I32: 18 | O32: =SUM(C32,G32,K32) -> 18 | P32: =SUM(D32,H32,L32) -> 18 | Q32: =IF(P32=0,"-",SUM(E32,I32,M32)) -> 18 | R32: =IF(P32=0,"-",SUM(F32,J32,N32)) -> 0 | S32: =IF(P32=0,"-",SUM((IF((E32+F32)>228,D32,IF((E32+F32)>D32,D32,(E32+F32)))),IF((I32+J32)>228,H32,IF((I32+J32)>H32,H32,(I32+J32))),(IF((M32+N32)>228,L32,IF((M32+N32)>L32,L32,(M32+N32)))))) -> 18 | T32: =IF(P32=0,"-",(P32-S32)) -> 0 | U32: =IF(P32=0,"-",(1-(T32/P32))) -> 1
B33: Reguladores de tensão de rede | C33: 4 | D33: 4 | E33: 4 | G33: 228 | H33: 228 | I33: 228 | K33: 11 | L33: 11 | M33: 11 | O33: =SUM(C33,G33,K33) -> 243 | P33: =SUM(D33,H33,L33) -> 243 | Q33: =IF(P33=0,"-",SUM(E33,I33,M33)) -> 243 | R33: =IF(P33=0,"-",SUM(F33,J33,N33)) -> 0 | S33: =IF(P33=0,"-",SUM((IF((E33+F33)>228,D33,IF((E33+F33)>D33,D33,(E33+F33)))),IF((I33+J33)>228,H33,IF((I33+J33)>H33,H33,(I33+J33))),(IF((M33+N33)>228,L33,IF((M33+N33)>L33,L33,(M33+N33)))))) -> 243 | T33: =IF(P33=0,"-",(P33-S33)) -> 0 | U33: =IF(P33=0,"-",(1-(T33/P33))) -> 1
B34: Outros equipamentos de pequeno porte e/ou rede | C34: 9 | D34: 9 | E34: 9 | G34: 45 | H34: 45 | I34: 45 | K34: 55 | L34: 55 | M34: 55 | O34: =SUM(C34,G34,K34) -> 109 | P34: =SUM(D34,H34,L34) -> 109 | Q34: =IF(P34=0,"-",SUM(E34,I34,M34)) -> 109 | R34: =IF(P34=0,"-",SUM(F34,J34,N34)) -> 0 | S34: =IF(P34=0,"-",SUM((IF((E34+F34)>228,D34,IF((E34+F34)>D34,D34,(E34+F34)))),IF((I34+J34)>228,H34,IF((I34+J34)>H34,H34,(I34+J34))),(IF((M34+N34)>228,L34,IF((M34+N34)>L34,L34,(M34+N34)))))) -> 109 | T34: =IF(P34=0,"-",(P34-S34)) -> 0 | U34: =IF(P34=0,"-",(1-(T34/P34))) -> 1
B35: TOTAIS | C35: =SUM(C30:C34) -> 28 | D35: =SUM(D30:D34) -> 28 | E35: =SUM(E30:E34) -> 28 | F35: =SUM(F30:F34) -> 0 | G35: =SUM(G30:G34) -> 305 | H35: =SUM(H30:H34) -> 305 | I35: =SUM(I30:I34) -> 305 | J35: =SUM(J30:J34) -> 0 | ... S35: =SUM(S30:S34) -> 399 | T35: =(P35-S35) -> 0 | U35: =IF(P35=0,"-",(1-(T35/P35))) -> 1
A38: EMS | B38: FAMÍLIA | C38: SUB-FAMÍLIAS | O38: TOTAIS | V38: OBSERVAÇÕES | AD38: Avanço 24 | AE38: Avanço 25
C39: Até 1988 | G39: Após 1988 | K39: Sem Info. | AD39: {=(SUM((IF(I41:I45<=H41:H45,I41:I45,H41:H45)),(IF(E41:E45<=D41:D45,E41:E45,D41:D45)),(IF(M41:M45<=L41:L45,M41:M45,L41:L45))))/P46} -> 0.38878843 | AE39: {=SUM((IF((E41:E45+F41:F45)>D41:D45,ABS(D41:D45-E41:E45),F41:F45)),(IF((I41:I45+J41:J45)>H41:H45,ABS(H41:H45-I41:I45),J41:J45)),(IF((M41:M45+N41:N45)>L41:L45,ABS(L41:L45-M41:M45),N41:N45)))/(P46-Q46)} -> 0.48816568
C40: Previsto | D40: Atualiz. | E40: Real. 24 | F40: Real. 25 | G40: Previsto | H40: Atualiz. | I40: Real. 24 | J40: Real. 25 | K40: Previsto | L40: Atualiz. | M40: Real. 24 | N40: Real. 25 | O40: Previstos | P40: Atualiz. | Q40: Real. 24 | R40: Real. 25 | S40: T. Consid. | T40: Fal. Teste | U40: Avanço | V40: 1 - Correção em cadastro para transformadores de RD subterrânea; 2 - Utilização de laudos obtidos pela ITB (313) para reguladores; 3 - Foram realizados 105 testes de TSAs usando testes rápidos em 2024. 4 - dos 124 OE ( chaves a Oleo), 28 já foram substituidas por CF. 80 realmente são CO e precisam ser identificadase testadas. A EMS substituiu os 14 TSAs anteriores a 88. Precisamos pegar documento comprovando
B41: Transformador de rede subterrânea | C41: 0 | G41: 64 | H41: 10 | K41: 167 | L41: 0 | O41: =SUM(C41,G41,K41) -> 231 | P41: =SUM(D41,H41,L41) -> 10 | Q41: =IF(P41=0,"-",SUM(E41,I41,M41)) -> 0 | R41: =IF(P41=0,"-",SUM(F41,J41,N41)) -> 0 | S41: =IF(P41=0,"-",SUM((IF((E41+F41)>228,D41,IF((E41+F41)>D41,D41,(E41+F41)))),IF((I41+J41)>228,H41,IF((I41+J41)>H41,H41,(I41+J41))),(IF((M41+N41)>228,L41,IF((M41+N41)>L41,L41,(M41+N41)))))) -> 0 | T41: =IF(P41=0,"-",(P41-S41)) -> 10 | U41: =IF(P41=0,"-",(1-(T41/P41))) -> 0
B42: Disjuntores com extinção de arco em OMI (PVO e GVO) | C42: 33 | D42: 33 | E42: 33 | G42: 5 | H42: 5 | I42: 5 | O42: =SUM(C42,G42,K42) -> 38 | P42: =SUM(D42,H42,L42) -> 38 | Q42: =IF(P42=0,"-",SUM(E42,I42,M42)) -> 38 | R42: =IF(P42=0,"-",SUM(F42,J42,N42)) -> 0 | S42: =IF(P42=0,"-",SUM((IF((E42+F42)>228,D42,IF((E42+F42)>D42,D42,(E42+F42)))),IF((I42+J42)>228,H42,IF((I42+J42)>H42,H42,(I42+J42))),(IF((M42+N42)>228,L42,IF((M42+N42)>L42,L42,(M42+N42)))))) -> 38 | T42: =IF(P42=0,"-",(P42-S42)) -> 0 | U42: =IF(P42=0,"-",(1-(T42/P42))) -> 1
B43: Religadores | C43: 2 | D43: 0 | G43: 139 | H43: 2 | K43: 5 | L43: 0 | O43: =SUM(C43,G43,K43) -> 146 | P43: =SUM(D43,H43,L43) -> 2 | Q43: =IF(P43=0,"-",SUM(E43,I43,M43)) -> 0 | R43: =IF(P43=0,"-",SUM(F43,J43,N43)) -> 0 | S43: =IF(P43=0,"-",SUM((IF((E43+F43)>228,D43,IF((E43+F43)>D43,D43,(E43+F43)))),IF((I43+J43)>228,H43,IF((I43+J43)>H43,H43,(I43+J43))),(IF((M43+N43)>228,L43,IF((M43+N43)>L43,L43,(M43+N43)))))) -> 0 | T43: =IF(P43=0,"-",(P43-S43)) -> 2 | U43: =IF(P43=0,"-",(1-(T43/P43))) -> 0
B44: Reguladores de tensão de rede | C44: 9 | D44: 9 | G44: 228 | H44: 228 | I44: 72 | J44: 313 | K44: 15 | L44: 15 | O44: =SUM(C44,G44,K44) -> 252 | P44: =SUM(D44,H44,L44) -> 252 | Q44: =IF(P44=0,"-",SUM(E44,I44,M44)) -> 72 | R44: =IF(P44=0,"-",SUM(F44,J44,N44)) -> 313 | S44: =IF(P44=0,"-",SUM((IF((E44+F44)>228,D44,IF((E44+F44)>D44,D44,(E44+F44)))),IF((I44+J44)>228,H44,IF((I44+J44)>H44,H44,(I44+J44))),(IF((M44+N44)>228,L44,IF((M44+N44)>L44,L44,(M44+N44)))))) -> 228 | T44: =IF(P44=0,"-",(P44-S44)) -> 24 | U44: =IF(P44=0,"-",(1-(T44/P44))) -> 0.9047619
B45: Outros equipamentos de pequeno porte e/ou rede | C45: 14 | D45: 14 | F45: 9 | G45: 113 | H45: 113 | I45: 105 | K45: 124 | L45: 124 | O45: =SUM(C45,G45,K45) -> 251 | P45: =SUM(D45,H45,L45) -> 251 | Q45: =IF(P45=0,"-",SUM(E45,I45,M45)) -> 105 | R45: =IF(P45=0,"-",SUM(F45,J45,N45)) -> 9 | S45: =IF(P45=0,"-",SUM((IF((E45+F45)>228,D45,IF((E45+F45)>D45,D45,(E45+F45)))),IF((I45+J45)>228,H45,IF((I45+J45)>H45,H45,(I45+J45))),(IF((M45+N45)>228,L45,IF((M45+N45)>L45,L45,(M45+N45)))))) -> 114 | T45: =IF(P45=0,"-",(P45-S45)) -> 137 | U45: =IF(P45=0,"-",(1-(T45/P45))) -> 0.45418327
B46: TOTAIS | C46: =SUM(C41:C45) -> 58 | D46: =SUM(D41:D45) -> 56 | E46: =SUM(E41:E45) -> 33 | F46: =SUM(F41:F45) -> 9 | G46: =SUM(G41:G45) -> 549 | H46: =SUM(H41:H45) -> 358 | I46: =SUM(I41:I45) -> 182 | J46: =SUM(J41:J45) -> 313 | ... S46: =SUM(S41:S45) -> 380 | T46: =(P46-S46) -> 173 | U46: =IF(P46=0,"-",(1-(T46/P46))) -> 0.68716094
A49: ETO | B49: FAMÍLIA | C49: SUB-FAMÍLIAS | O49: TOTAIS | V49: OBSERVAÇÕES | AD49: Avanço 24 | AE49: Avanço 25
C50: Até 1988 | G50: Após 1988 | K50: Sem Info. | AD50: {=(SUM((IF(I52:I56<=H52:H56,I52:I56,H52:H56)),(IF(E52:E56<=D52:D56,E52:E56,D52:D56)),(IF(M52:M56<=L52:L56,M52:M56,L52:L56))))/P57} -> 0.38418079 | AE50: {=SUM((IF((E52:E56+F52:F56)>D52:D56,ABS(D52:D56-E52:E56),F52:F56)),(IF((I52:I56+J52:J56)>H52:H56,ABS(H52:H56-I52:I56),J52:J56)),(IF((M52:M56+N52:N56)>L52:L56,ABS(L52:L56-M52:M56),N52:N56)))/(P57-Q57)} -> 0.52293578
C51: Previsto | D51: Atualiz. | E51: Real. 24 | F51: Real. 25 | G51: Previsto | H51: Atualiz. | I51: Real. 24 | J51: Real. 25 | K51: Previsto | L51: Atualiz. | M51: Real. 24 | N51: Real. 25 | O51: Previstos | P51: Atualiz. | Q51: Real. 24 | R51: Real. 25 | S51: T. Consid. | T51: Fal. Teste | U51: Avanço | V51: 1 - Foram considerados 215 laudos/testes via documentação emitida pela ITB. 2 - no item "RT Sem Data" foram reclassificados 97 para "RT Após 1988" por compravar a existência de identificação. 3 - 42 TSAs coletados em ago/25. Aguardando resultados
...

Sheet Planilha2
C1: Informações | D1: Linkagem do laudo
B2: EMS
B3: EAC
B4: EMT
B5: ESE
B6: ESS
B7: ETO
B8: ERO
B9: EMR
B10: EPB

Sheet EMS
B1: Informações de Testes Realizados
B4: =_xlfn.CONCAT("Transformadores de Rede Subterrânea",TEXT(IF(SUM(J11:J13)=0," ",(SUM(H11:H13)/SUM(J11:J13))), " 0,00%")) -> Transformadores de Rede Subterrânea
B5: ID | C5: Sub-Família | D5: Descrição | F5: N. Série | G5: Tombamento | H5: Ano de Fabricação | I5: N. Operativo | J5: Data Análise | K5: Tipo Análise | L5: Resultado | M5: Evidência de Teste
B6: =IF(C6="","",ROW($A$1))
B7: =IF(C7="","",(B6+1))
B8: =IF(C8="","",(B7+1))
B9: Totais
B10: Sub-Família | C10: Equipamentos | D10: Isentos | E10: Não Contaminados | F10: Contaminados | G10: PCB | H10: Testes Realizados | I10: Tx. Contaminação | J10: Meta Manual | K10: Avanço 24 | L10: Avanço 25 | M10: Avanço Meta Manual
B11: Até 1988 | C11: =COUNTIFS(B6:B8,">"&0,C6:C8,"="&B11) -> 0 | D11: =COUNTIFS(B6:B8,">="&1,C6:C8,B11,L6:L8,"<"&2,L6:L8,">="&0) -> 0 | E11: =COUNTIFS(B6:B8,">="&1,C6:C8,B11,L6:L8,">="&2,L6:L8,"<"&50) -> 0 | F11: =_xlfn.CONCAT(COUNTIFS(B6:B8,">="&1,C6:C8,B11,L6:L8,">="&50,L6:L8,"<"&500)," - ",TEXT((COUNTIFS(B6:B8,">="&1,C6:C8,B11,L6:L8,">="&50,L6:L8,"<"&500)/IF(H11=0,1,H11)),"0,0%")) -> 0 - 0,0% | G11: =_xlfn.CONCAT(COUNTIFS(B6:B8,">="&1,C6:C8,B11,L6:L8,">="&500)," - ",TEXT((COUNTIFS(B6:B8,">="&1,C6:C8,B11,L6:L8,">="&500)/IF(H11=0,1,H11)),"0,0%")) -> 0 - 0,0% | H11: =COUNTIFS(B6:B8,">="&1,C6:C8,B11,L6:L8,">="&0,J6:J8,">"&DATE(2021,1,1)) -> 0 | I11: =IF(H11=0,"-",(COUNTIFS(B6:B8,">="&1,J6:J8,"<>"&"",L6:L8,">="&50)/H11)) -> - | J11: =IF((COUNTIFS(B6:B8,">="&1,C6:C8,"="&B11))>228,228,(COUNTIFS(B6:B8,">="&1,C6:C8,"="&B11))) -> 0 | K11: =IF(J11=0,"-",(COUNTIFS(C6:C8,"="&B11,J6:J8,"<="&DATE(2024,12,31),L6:L8,">="&0)/J11)) -> - | L11: =IF(J11=0,"-",IF(K11=1,"-",(COUNTIFS(B6:B8,">"&0,C6:C8,"="&B11,J6:J8,">"&DATE(2024,12,31),L6:L8,">="&0)/(J11-COUNTIFS(B6:B8,">"&0,C6:C8,"="&B11,J6:J8,"<="&DATE(2024,12,31),L6:L8,">="&0))))) -> - | M11: =IF(J11=0,"-",H11/J11) -> -
B12: Após 1988 | C12: =COUNTIFS(B6:B8,">"&0,C6:C8,"="&B12) -> 0 | D12: =COUNTIFS(B6:B8,">="&1,C6:C8,B12,L6:L8,"<"&2,L6:L8,">="&0) -> 0 | E12: =COUNTIFS(B6:B8,">="&1,C6:C8,B12,L6:L8,">="&2,L6:L8,"<"&50) -> 0 | F12: =_xlfn.CONCAT(COUNTIFS(B6:B8,">="&1,C6:C8,B12,L6:L8,">="&50,L6:L8,"<"&500)," - ",TEXT((COUNTIFS(B6:B8,">="&1,C6:C8,B12,L6:L8,">="&50,L6:L8,"<"&500)/IF(H12=0,1,H12)),"0,0%")) -> 0 - 0,0% | G12: =_xlfn.CONCAT(COUNTIFS(B6:B8,">="&1,C6:C8,B12,L6:L8,">="&500)," - ",TEXT((COUNTIFS(B6:B8,">="&1,C6:C8,B12,L6:L8,">="&500)/IF(H12=0,1,H12)),"0,0%")) -> 0 - 0,0% | H12: =COUNTIFS(B6:B8,">="&1,C6:C8,B12,L6:L8,">="&0,J6:J8,">"&DATE(2021,1,1)) -> 0 | I12: =IF(H12=0,"-",(COUNTIFS(B6:B8,">="&1,J6:J8,"<>"&"",L6:L8,">="&50)/H12)) -> - | J12: =IF((COUNTIFS(B6:B8,">="&1,C6:C8,"="&B12))>228,228,(COUNTIFS(B6:B8,">="&1,C6:C8,"="&B12))) -> 0 | K12: =IF(J12=0,"-",(COUNTIFS(C6:C8,"="&B12,J6:J8,"<="&DATE(2024,12,31),L6:L8,">="&0)/J12)) -> - | L12: =IF(J12=0,"-",IF(K12=1,"-",(COUNTIFS(B6:B8,">"&0,C6:C8,"="&B12,J6:J8,">"&DATE(2024,12,31),L6:L8,">="&0)/(J12-COUNTIFS(B6:B8,">"&0,C6:C8,"="&B12,J6:J8,"<="&DATE(2024,12,31),L6:L8,">="&0))))) -> - | M12: =IF(J12=0,"-",H12/J12) -> -
B13: Sem Info | C13: =COUNTIFS(B6:B8,">"&0,C6:C8,"="&B13) -> 0 | D13: =COUNTIFS(B6:B8,">="&1,C6:C8,B13,L6:L8,"<"&2,L6:L8,">="&0) -> 0 | E13: =COUNTIFS(B6:B8,">="&1,C6:C8,B13,L6:L8,">="&2,L6:L8,"<"&50) -> 0 | F13: =_xlfn.CONCAT(COUNTIFS(B6:B8,">="&1,C6:C8,B13,L6:L8,">="&50,L6:L8,"<"&500)," - ",TEXT((COUNTIFS(B6:B8,">="&1,C6:C8,B13,L6:L8,">="&50,L6:L8,"<"&500)/IF(H13=0,1,H13)),"0,0%")) -> 0 - 0,0% | G13: =_xlfn.CONCAT(COUNTIFS(B6:B8,">="&1,C6:C8,B13,L6:L8,">="&500)," - ",TEXT((COUNTIFS(B6:B8,">="&1,C6:C8,B13,L6:L8,">="&500)/IF(H13=0,1,H13)),"0,0%")) -> 0 - 0,0% | H13: =COUNTIFS(B6:B8,">="&1,C6:C8,B13,L6:L8,">="&0,J6:J8,">"&DATE(2021,1,1)) -> 0 | I13: =IF(H13=0,"-",(COUNTIFS(B6:B8,">="&1,J6:J8,"<>"&"",L6:L8,">="&50)/H13)) -> - | J13: =IF((COUNTIFS(B6:B7,">="&1,C6:C7,"="&B13))>228,228,(COUNTIFS(B6:B7,">="&1,C6:C7,"="&B13))) -> 0 | K13: =IF(J13=0,"-",(COUNTIFS(C6:C8,"="&B13,J6:J8,"<="&DATE(2024,12,31),L6:L8,">="&0)/J13)) -> - | L13: =IF(J13=0,"-",IF(K13=1,"-",(COUNTIFS(B6:B8,">"&0,C6:C8,"="&B13,J6:J8,">"&DATE(2024,12,31),L6:L8,">="&0)/(J13-COUNTIFS(B6:B8,">"&0,C6:C8,"="&B13,J6:J8,"<="&DATE(2024,12,31),L6:L8,">="&0))))) -> - | M13: =IF(J13=0,"-",H13/J13) -> -
B14: Totais | C14: =SUM(C11:C13) -> 0 | D14: =SUM(D11:D13) -> 0 | E14: =SUM(E11:E13) -> 0 | F14: =COUNTIFS(B6:B8,">="&1,L6:L8,">="&50,L6:L8,"<"&500) -> 0 | G14: =COUNTIFS(B6:B8,">="&1,L6:L8,">="&500) -> 0 | H14: =SUM(H11:H13) -> 0 | I14: =IF(H14=0,"-",(SUM(F14,G14)/H14)) -> - | J14: =SUM(J11:J13) -> 0 | K14: =IF(J14=0,"-",(COUNTIFS(J6:J8,"<="&DATE(2024,12,31),L6:L8,">="&0)/J14)) -> - | L14: =IF(J14=0,"-",IF(K14=1,"-",(COUNTIFS(B6:B8,">"&0,J6:J8,">"&DATE(2024,12,31),L6:L8,">="&0)/(J14-COUNTIFS(B6:B8,">"&0,J6:J8,"<="&DATE(2024,12,31),L6:L8,">="&0))))) -> - | M14: =IF(J14=0,"-",H14/J14) -> -
B17: =_xlfn.CONCAT("Disjuntores com extinção de arco OMI (PVO e GVO)",TEXT(IF(SUM(J51:J53)=0," ",(SUM(H51:H53)/SUM(J51:J53))), " 0,00%")) -> Disjuntores com extinção de arco OMI (PVO e GVO)
B18: ID | C18: Sub-Família | E18: Descrição | F18: N. Série | G18: Tombamento | H18: Ano de Fabricação | I18: N. Operativo | J18: Data Análise | K18: Tipo Análise | L18: Resultado | M18: Evidência de Teste
B19: =IF(C19="","",ROW($A$1))
B20: =IF(C20="","",B19+1)
B21: =IF(C21="","",B20+1)
B22: =IF(C22="","",B21+1)
B23: =IF(C23="","",B22+1)
B24: =IF(C24="","",B23+1)
B25: =IF(C25="","",B24+1)
B26: =IF(C26="","",B25+1)
B27: =IF(C27="","",B26+1)
B28: =IF(C28="","",B27+1)
B29: =IF(C29="","",B28+1)
B30: =IF(C30="","",B29+1)
B31: =IF(C31="","",B30+1)
... B48: =IF(C48="","",B47+1)
B49: Totais
B50: Sub-Família | C50: Equipamentos | D50: Isentos | E50: Não Contaminados | F50: Contaminados | G50: PCB | H50: Testes Realizados | I50: Tx. Contaminação | J50: Meta Manual | K50: Avanço 24 | L50: Avanço 25 | M50: Avanço Meta Manual
B51: Até 1988 | C51: =COUNTIFS(B19:B48,">"&0,C19:C48,"="&B51) -> 0 | E51: =COUNTIFS(B19:B48,">="&1,C19:C48,B51,L19:L48,">="&0,L19:L48,"<"&50) -> 0 | F51: =COUNTIFS(B19:B48,">="&1,C19:C48,B51,L19:L48,">="&50,L19:L48,"<"&500) -> 0 | G51: =COUNTIFS(B19:B48,">="&1,C19:C48,B51,L19:L48,">="&500) -> 0 | H51: =COUNTIFS(B19:B48,">="&1,C19:C48,B51,L19:L48,">="&0,J19:J48,">"&DATE(2021,1,1)) -> 0 | I51: =IF(H51=0,"-",(SUM(F51,G51)/H51)) -> - | J51: =IF((COUNTIFS(B19:B48,">="&1,C19:C48,"="&B51))>228,228,(COUNTIFS(B19:B48,">="&1,C19:C48,"="&B51))) -> 0 | K51: =IF(J51=0,"-",(COUNTIFS(C19:C48,"="&B51,J19:J48,"<="&DATE(2024,12,31),L19:L48,">="&0)/J51)) -> - | L51: =IF(J51=0,"-",IF(K51=1,"-",(COUNTIFS(B19:B48,">"&0,C19:C48,"="&B51,J19:J48,">"&DATE(2024,12,31),L19:L48,">="&0)/(J51-COUNTIFS(B19:B48,">"&0,C19:C48,"="&B51,J19:J48,"<="&DATE(2024,12,31),L19:L48,">="&0))))) -> - | M51: =IF(J51=0,"-",H51/J51) -> -
B52: Após 1988 | C52: =COUNTIFS(B19:B48,">"&0,C19:C48,"="&B52) -> 0 | E52: =COUNTIFS(B19:B48,">="&1,C19:C48,B52,L19:L48,">="&0,L19:L48,"<"&50) -> 0 | F52: =COUNTIFS(B19:B48,">="&1,C19:C48,B52,L19:L48,">="&50,L19:L48,"<"&500) -> 0 | G52: =COUNTIFS(B19:B48,">="&1,C19:C48,B52,L19:L48,">="&500) -> 0 | H52: =COUNTIFS(B19:B48,">="&1,C19:C48,B52,L19:L48,">="&0,J19:J48,">"&DATE(2021,1,1)) -> 0 | I52: =IF(H52=0,"-",(SUM(F52,G52)/H52)) -> - | J52: =IF((COUNTIFS(B19:B48,">="&1,C19:C48,"="&B52))>228,228,(COUNTIFS(B19:B48,">="&1,C19:C48,"="&B52))) -> 0 | K52: =IF(J52=0,"-",(COUNTIFS(C19:C48,"="&B52,J19:J48,"<="&DATE(2024,12,31),L19:L48,">="&0)/J52)) -> - | L52: =IF(J52=0,"-",IF(K52=1,"-",(COUNTIFS(B19:B48,">"&0,C19:C48,"="&B52,J19:J48,">"&DATE(2024,12,31),L19:L48,">="&0)/(J52-COUNTIFS(B19:B48,">"&0,C19:C48,"="&B52,J19:J48,"<="&DATE(2024,12,31),L19:L48,">="&0))))) -> - | M52: =IF(J52=0,"-",H52/J52) -> -
B53: Sem Info | C53: =COUNTIFS(B19:B48,">"&0,C19:C48,"="&B53) -> 0 | E53: =COUNTIFS(B19:B48,">="&1,C19:C48,B53,L19:L48,">="&0,L19:L48,"<"&50) -> 0 | F53: =COUNTIFS(B19:B48,">="&1,C19:C48,B53,L19:L48,">="&50,L19:L48,"<"&500) -> 0 | G53: =COUNTIFS(B19:B47,">="&1,C19:C47,B53,L19:L47,">="&500) -> 0 | H53: =COUNTIFS(B19:B48,">="&1,C19:C48,B53,L19:L48,">="&0,J19:J48,">"&DATE(2021,1,1)) -> 0 | I53: =IF(H53=0,"-",(SUM(F53,G53)/H53)) -> - | J53: =IF((COUNTIFS(B19:B47,">="&1,C19:C47,"="&B53))>228,228,(COUNTIFS(B19:B47,">="&1,C19:C47,"="&B53))) -> 0 | K53: =IF(J53=0,"-",(COUNTIFS(C19:C48,"="&B53,J19:J48,"<="&DATE(2024,12,31),L19:L48,">="&0)/J53)) -> - | L53: =IF(J53=0,"-",IF(K53=1,"-",(COUNTIFS(B19:B48,">"&0,C19:C48,"="&B53,J19:J48,">"&DATE(2024,12,31),L19:L48,">="&0)/(J53-COUNTIFS(B19:B48,">"&0,C19:C48,"="&B53,J19:J48,"<="&DATE(2024,12,31),L19:L48,">="&0))))) -> - | M53: =IF(J53=0,"-",H53/J53) -> -
B54: Totais | C54: =SUM(C51:C53) -> 0 | E54: =SUM(E51:E53) -> 0 | F54: =SUM(F51:F53) -> 0 | G54: =SUM(G51:G53) -> 0 | H54: =SUM(H51:H53) -> 0 | I54: =IF(H54=0,"-",(SUM(F54,G54)/H54)) -> - | J54: =SUM(J51:J53) -> 0 | K54: =IF(J54=0,"-",(COUNTIFS(J19:J48,"<="&DATE(2024,12,31),L19:L48,">="&0)/J54)) -> - | L54: =IF(J54=0,"-",IF(K54=1,"-",(COUNTIFS(B19:B48,">"&0,J19:J48,">"&DATE(2024,12,31),L19:L48,">="&0)/(J54-COUNTIFS(B19:B48,">"&0,J19:J48,"<="&DATE(2024,12,31),L19:L48,">="&0))))) -> - | M54: =IF(J54=0,"-",H54/J54) -> -
B57: =_xlfn.CONCAT("Religadores",TEXT(IF(SUM(J83:J85)=0," ",(SUM(H83:H85)/SUM(J83:J85))), " 0,00%")) -> Religadores
B58: ID | C58: Sub-Família | E58: Descrição | F58: N. Série | G58: Tombamento | H58: Ano de Fabricação | I58: N. Operativo | J58: Data Análise | K58: Tipo Análise | L58: Resultado | M58: Evidência de Teste
B59: =IF(C59="","",ROW($A$1))
B60: =IF(C60="","",(B59+1))
B61: =IF(C61="","",(B60+1))
B62: =IF(C62="","",(B61+1))
...

Sheet EAC
B1: Informações de Testes Realizados
B4: =_xlfn.CONCAT("Transformadores de Rede Subterrânea",TEXT(IF(SUM(I11:I13)=0," ",(SUM(G11:G13)/SUM(I11:I13))), " 0,00%")) -> Transformadores de Rede Subterrânea
B5: ID | C5: Sub-Família | D5: Descrição | E5: N. Série | F5: Tombamento | G5: Ano de Fabricação | H5: N. Operativo | I5: Data Análise | J5: Tipo Análise | K5: Resultado | L5: Evidência de Teste
B6: =IF(C6="","",ROW($A$1))
B7: =IF(B6="","",(B6+1))
B9: Totais
B10: Sub-Família | C10: Equipamentos | D10: Não Contaminados | E10: Contaminados | F10: PCB | G10: Testes Realizados | H10: Tx. Contaminação | I10: Meta Manual | J10: Avanço 24 | K10: Avanço 25 | L10: Avanço Meta Manual
B11: Até 1988 | C11: =COUNTIFS(B6:B8,">"&0,C6:C8,"="&B11) -> 0 | D11: =COUNTIFS(B6:B8,">="&1,C6:C8,B11,K6:K8,">="&0,K6:K8,"<"&50) -> 0 | E11: =COUNTIFS(B6:B8,">="&1,C6:C8,B11,K6:K8,">="&50,K6:K8,"<"&500) -> 0 | F11: =COUNTIFS(B6:B8,">="&1,C6:C8,B11,K6:K8,">="&500) -> 0 | G11: =COUNTIFS(B6:B8,">="&1,C6:C8,B11,K6:K8,">="&0,I6:I8,">"&DATE(2021,1,1)) -> 0 | H11: =IF(G11=0,"-",(SUM(E11,F11)/G11)) -> - | I11: =IF((COUNTIFS(B6:B8,">="&1,C6:C8,"="&B11))>228,228,(COUNTIFS(B6:B8,">="&1,C6:C8,"="&B11))) -> 0 | J11: =IF(I11=0,"-",(COUNTIFS(C6:C8,"="&B11,I6:I8,"<="&DATE(2024,12,31),K6:K8,">="&0)/I11)) -> - | K11: =IF(I11=0,"-",IF(J11=1,"-",(COUNTIFS(B6:B8,">"&0,C6:C8,"="&B11,I6:I8,">"&DATE(2024,12,31),K6:K8,">="&0)/(I11-COUNTIFS(B6:B8,">"&0,C6:C8,"="&B11,I6:I8,"<="&DATE(2024,12,31),K6:K8,">="&0))))) -> - | L11: =IF(I11=0,"-",G11/I11) -> -
B12: Após 1988 | C12: =COUNTIFS(B6:B8,">"&0,C6:C8,"="&B12) -> 0 | D12: =COUNTIFS(B6:B8,">="&1,C6:C8,B12,K6:K8,">="&0,K6:K8,"<"&50) -> 0 | E12: =COUNTIFS(B6:B8,">="&1,C6:C8,B12,K6:K8,">="&50,K6:K8,"<"&500) -> 0 | F12: =COUNTIFS(B6:B8,">="&1,C6:C8,B12,K6:K8,">="&500) -> 0 | G12: =COUNTIFS(B6:B8,">="&1,C6:C8,B12,K6:K8,">="&0,I6:I8,">"&DATE(2021,1,1)) -> 0 | H12: =IF(G12=0,"-",(SUM(E12,F12)/G12)) -> - | I12: =IF((COUNTIFS(B6:B8,">="&1,C6:C8,"="&B12))>228,228,(COUNTIFS(B6:B8,">="&1,C6:C8,"="&B12))) -> 0 | J12: =IF(I12=0,"-",(COUNTIFS(C6:C8,"="&B12,I6:I8,"<="&DATE(2024,12,31),K6:K8,">="&0)/I12)) -> - | K12: =IF(I12=0,"-",IF(J12=1,"-",(COUNTIFS(B6:B8,">"&0,C6:C8,"="&B12,I6:I8,">"&DATE(2024,12,31),K6:K8,">="&0)/(I12-COUNTIFS(B6:B8,">"&0,C6:C8,"="&B12,I6:I8,"<="&DATE(2024,12,31),K6:K8,">="&0))))) -> - | L12: =IF(I12=0,"-",G12/I12) -> -
B13: Sem Info | C13: =COUNTIFS(B6:B8,">"&0,C6:C8,"="&B13) -> 0 | D13: =COUNTIFS(B6:B8,">="&1,C6:C8,B13,K6:K8,">="&0,K6:K8,"<"&50) -> 0 | E13: =COUNTIFS(B6:B8,">="&1,C6:C8,B13,K6:K8,">="&50,K6:K8,"<"&500) -> 0 | F13: =COUNTIFS(B6:B7,">="&1,C6:C7,B13,K6:K7,">="&500) -> 0 | G13: =COUNTIFS(B6:B8,">="&1,C6:C8,B13,K6:K8,">="&0,I6:I8,">"&DATE(2021,1,1)) -> 0 | H13: =IF(G13=0,"-",(SUM(E13,F13)/G13)) -> - | I13: =IF((COUNTIFS(B6:B7,">="&1,C6:C7,"="&B13))>228,228,(COUNTIFS(B6:B7,">="&1,C6:C7,"="&B13))) -> 0 | J13: =IF(I13=0,"-",(COUNTIFS(C6:C8,"="&B13,I6:I8,"<="&DATE(2024,12,31),K6:K8,">="&0)/I13)) -> - | K13: =IF(I13=0,"-",IF(J13=1,"-",(COUNTIFS(B6:B8,">"&0,C6:C8,"="&B13,I6:I8,">"&DATE(2024,12,31),K6:K8,">="&0)/(I13-COUNTIFS(B6:B8,">"&0,C6:C8,"="&B13,I6:I8,"<="&DATE(2024,12,31),K6:K8,">="&0))))) -> - | L13: =IF(I13=0,"-",G13/I13) -> -
B14: Totais | C14: =SUM(C11:C13) -> 0 | D14: =SUM(D11:D13) -> 0 | E14: =SUM(E11:E13) -> 0 | F14: =SUM(F11:F13) -> 0 | G14: =SUM(G11:G13) -> 0 | H14: =IF(G14=0,"-",(SUM(E14,F14)/G14)) -> - | I14: =SUM(I11:I13) -> 0 | J14: =IF(I14=0,"-",(COUNTIFS(I6:I8,"<="&DATE(2024,12,31),K6:K8,">="&0)/I14)) -> - | K14: =IF(I14=0,"-",IF(J14=1,"-",(COUNTIFS(B6:B8,">"&0,I6:I8,">"&DATE(2024,12,31),K6:K8,">="&0)/(I14-COUNTIFS(B6:B8,">"&0,I6:I8,"<="&DATE(2024,12,31),K6:K8,">="&0))))) -> - | L14: =IF(I14=0,"-",G14/I14) -> -
B17: =_xlfn.CONCAT("Disjuntores com extinção de arco OMI (PVO e GVO)",TEXT(IF(SUM(I51:I53)=0," ",(SUM(G51:G53)/SUM(I51:I53))), " 0,00%")) -> Disjuntores com extinção de arco OMI (PVO e GVO)
B18: ID | C18: Sub-Família | D18: Descrição | E18: N. Série | F18: Tombamento | G18: Ano de Fabricação | H18: N. Operativo | I18: Data Análise | J18: Tipo Análise | K18: Resultado | L18: Evidência de Teste
B19: =IF(C19="","",ROW($A$1))
B20: =IF(C20="","",B19+1)
B21: =IF(C21="","",B20+1)
B22: =IF(C22="","",B21+1)
B23: =IF(C23="","",B22+1)
B24: =IF(C24="","",B23+1)
B25: =IF(C25="","",B24+1)
B26: =IF(C26="","",B25+1)
B27: =IF(C27="","",B26+1)
B28: =IF(C28="","",B27+1)
B29: =IF(C29="","",B28+1)
B30: =IF(C30="","",B29+1)
B31: =IF(C31="","",B30+1)
... B48: =IF(C48="","",B47+1)
B49: Totais
B50: Sub-Família | C50: Equipamentos | D50: Não Contaminados | E50: Contaminados | F50: PCB | G50: Testes Realizados | H50: Tx. Contaminação | I50: Meta Manual | J50: Avanço 24 | K50: Avanço 25 | L50: Avanço Meta Manual
B51: Até 1988 | C51: =COUNTIFS(B19:B48,">"&0,C19:C48,"="&B51) -> 0 | D51: =COUNTIFS(B19:B48,">="&1,C19:C48,B51,K19:K48,">="&0,K19:K48,"<"&50) -> 0 | E51: =COUNTIFS(B19:B48,">="&1,C19:C48,B51,K19:K48,">="&50,K19:K48,"<"&500) -> 0 | F51: =COUNTIFS(B19:B48,">="&1,C19:C48,B51,K19:K48,">="&500) -> 0 | G51: =COUNTIFS(B19:B48,">="&1,C19:C48,B51,K19:K48,">="&0,I19:I48,">"&DATE(2021,1,1)) -> 0 | H51: =IF(G51=0,"-",(SUM(E51,F51)/G51)) -> - | I51: =IF((COUNTIFS(B19:B48,">="&1,C19:C48,"="&B51))>228,228,(COUNTIFS(B19:B48,">="&1,C19:C48,"="&B51))) -> 0 | J51: =IF(I51=0,"-",(COUNTIFS(C19:C48,"="&B51,I19:I48,"<="&DATE(2024,12,31),K19:K48,">="&0)/I51)) -> - | K51: =IF(I51=0,"-",IF(J51=1,"-",(COUNTIFS(B19:B48,">"&0,C19:C48,"="&B51,I19:I48,">"&DATE(2024,12,31),K19:K48,">="&0)/(I51-COUNTIFS(B19:B48,">"&0,C19:C48,"="&B51,I19:I48,"<="&DATE(2024,12,31),K19:K48,">="&0))))) -> - | L51: =IF(I51=0,"-",G51/I51) -> -
B52: Após 1988 | C52: =COUNTIFS(B19:B48,">"&0,C19:C48,"="&B52) -> 0 | D52: =COUNTIFS(B19:B48,">="&1,C19:C48,B52,K19:K48,">="&0,K19:K48,"<"&50) -> 0 | E52: =COUNTIFS(B19:B48,">="&1,C19:C48,B52,K19:K48,">="&50,K19:K48,"<"&500) -> 0 | F52: =COUNTIFS(B19:B48,">="&1,C19:C48,B52,K19:K48,">="&500) -> 0 | G52: =COUNTIFS(B19:B48,">="&1,C19:C48,B52,K19:K48,">="&0,I19:I48,">"&DATE(2021,1,1)) -> 0 | H52: =IF(G52=0,"-",(SUM(E52,F52)/G52)) -> - | I52: =IF((COUNTIFS(B19:B48,">="&1,C19:C48,"="&B52))>228,228,(COUNTIFS(B19:B48,">="&1,C19:C48,"="&B52))) -> 0 | J52: =IF(I52=0,"-",(COUNTIFS(C19:C48,"="&B52,I19:I48,"<="&DATE(2024,12,31),K19:K48,">="&0)/I52)) -> - | K52: =IF(I52=0,"-",IF(J52=1,"-",(COUNTIFS(B19:B48,">"&0,C19:C48,"="&B52,I19:I48,">"&DATE(2024,12,31),K19:K48,">="&0)/(I52-COUNTIFS(B19:B48,">"&0,C19:C48,"="&B52,I19:I48,"<="&DATE(2024,12,31),K19:K48,">="&0))))) -> - | L52: =IF(I52=0,"-",G52/I52) -> -
B53: Sem Info | C53: =COUNTIFS(B19:B48,">"&0,C19:C48,"="&B53) -> 0 | D53: =COUNTIFS(B19:B48,">="&1,C19:C48,B53,K19:K48,">="&0,K19:K48,"<"&50) -> 0 | E53: =COUNTIFS(B19:B48,">="&1,C19:C48,B53,K19:K48,">="&50,K19:K48,"<"&500) -> 0 | F53: =COUNTIFS(B19:B47,">="&1,C19:C47,B53,K19:K47,">="&500) -> 0 | G53: =COUNTIFS(B19:B48,">="&1,C19:C48,B53,K19:K48,">="&0,I19:I48,">"&DATE(2021,1,1)) -> 0 | H53: =IF(G53=0,"-",(SUM(E53,F53)/G53)) -> - | I53: =IF((COUNTIFS(B19:B47,">="&1,C19:C47,"="&B53))>228,228,(COUNTIFS(B19:B47,">="&1,C19:C47,"="&B53))) -> 0 | J53: =IF(I53=0,"-",(COUNTIFS(C19:C48,"="&B53,I19:I48,"<="&DATE(2024,12,31),K19:K48,">="&0)/I53)) -> - | K53: =IF(I53=0,"-",IF(J53=1,"-",(COUNTIFS(B19:B48,">"&0,C19:C48,"="&B53,I19:I48,">"&DATE(2024,12,31),K19:K48,">="&0)/(I53-COUNTIFS(B19:B48,">"&0,C19:C48,"="&B53,I19:I48,"<="&DATE(2024,12,31),K19:K48,">="&0))))) -> - | L53: =IF(I53=0,"-",G53/I53) -> -
B54: Totais | C54: =SUM(C51:C53) -> 0 | D54: =SUM(D51:D53) -> 0 | E54: =SUM(E51:E53) -> 0 | F54: =SUM(F51:F53) -> 0 | G54: =SUM(G51:G53) -> 0 | H54: =IF(G54=0,"-",(SUM(E54,F54)/G54)) -> - | I54: =SUM(I51:I53) -> 0 | J54: =IF(I54=0,"-",(COUNTIFS(I19:I48,"<="&DATE(2024,12,31),K19:K48,">="&0)/I54)) -> - | K54: =IF(I54=0,"-",IF(J54=1,"-",(COUNTIFS(B19:B48,">"&0,I19:I48,">"&DATE(2024,12,31),K19:K48,">="&0)/(I54-COUNTIFS(B19:B48,">"&0,I19:I48,"<="&DATE(2024,12,31),K19:K48,">="&0))))) -> - | L54: =IF(I54=0,"-",G54/I54) -> -
B57: =_xlfn.CONCAT("Religadores",TEXT(IF(SUM(I83:I85)=0," ",(SUM(G83:G85)/SUM(I83:I85))), " 0,00%")) -> Religadores
B58: ID | C58: Sub-Família | D58: Descrição | E58: N. Série | F58: Tombamento | G58: Ano de Fabricação | H58: N. Operativo | I58: Data Análise | J58: Tipo Análise | K58: Resultado | L58: Evidência de Teste
B59: =IF(C59="","",ROW($A$1))
B60: =IF(C60="","",(B59+1))
B61: =IF(C61="","",(B60+1))
B62: =IF(C62="","",(B61+1))
B63: =IF(C63="","",(B62+1))
...

Sheet EMT
B1: Informações de Testes Realizados
B4: =_xlfn.CONCAT("Transformadores de Rede Subterrânea",TEXT(IF(SUM(I11:I13)=0," ",(SUM(G11:G13)/SUM(I11:I13))), " 0,00%")) -> Transformadores de Rede Subterrânea
B5: ID | C5: Sub-Família | D5: Descrição | E5: N. Série | F5: Tombamento | G5: Ano de Fabricação | H5: N. Operativo | I5: Data Análise | J5: Tipo Análise | K5: Resultado | L5: Evidência de Teste
B6: =IF(C6="","",ROW($A$1))
B7: =IF(B6="","",(B6+1))
B9: Totais
B10: Sub-Família | C10: Equipamentos | D10: Não Contaminados | E10: Contaminados | F10: PCB | G10: Testes Realizados | H10: Tx. Contaminação | I10: Meta Manual | J10: Avanço 24 | K10: Avanço 25 | L10: Avanço Meta Manual
B11: Até 1988 | C11: =COUNTIFS(B6:B8,">"&0,C6:C8,"="&B11) -> 0 | D11: =COUNTIFS(B6:B8,">="&1,C6:C8,B11,K6:K8,">="&0,K6:K8,"<"&50) -> 0 | E11: =COUNTIFS(B6:B8,">="&1,C6:C8,B11,K6:K8,">="&50,K6:K8,"<"&500) -> 0 | F11: =COUNTIFS(B6:B8,">="&1,C6:C8,B11,K6:K8,">="&500) -> 0 | G11: =COUNTIFS(B6:B8,">="&1,C6:C8,B11,K6:K8,">="&0,I6:I8,">"&DATE(2021,1,1)) -> 0 | H11: =IF(G11=0,"-",(SUM(E11,F11)/G11)) -> - | I11: =IF((COUNTIFS(B6:B8,">="&1,C6:C8,"="&B11))>228,228,(COUNTIFS(B6:B8,">="&1,C6:C8,"="&B11))) -> 0 | J11: =IF(I11=0,"-",(COUNTIFS(C6:C8,"="&B11,I6:I8,"<="&DATE(2024,12,31),K6:K8,">="&0)/I11)) -> - | K11: =IF(I11=0,"-",IF(J11=1,"-",(COUNTIFS(B6:B8,">"&0,C6:C8,"="&B11,I6:I8,">"&DATE(2024,12,31),K6:K8,">="&0)/(I11-COUNTIFS(B6:B8,">"&0,C6:C8,"="&B11,I6:I8,"<="&DATE(2024,12,31),K6:K8,">="&0))))) -> - | L11: =IF(I11=0,"-",G11/I11) -> -
B12: Após 1988 | C12: =COUNTIFS(B6:B8,">"&0,C6:C8,"="&B12) -> 0 | D12: =COUNTIFS(B6:B8,">="&1,C6:C8,B12,K6:K8,">="&0,K6:K8,"<"&50) -> 0 | E12: =COUNTIFS(B6:B8,">="&1,C6:C8,B12,K6:K8,">="&50,K6:K8,"<"&500) -> 0 | F12: =COUNTIFS(B6:B8,">="&1,C6:C8,B12,K6:K8,">="&500) -> 0 | G12: =COUNTIFS(B6:B8,">="&1,C6:C8,B12,K6:K8,">="&0,I6:I8,">"&DATE(2021,1,1)) -> 0 | H12: =IF(G12=0,"-",(SUM(E12,F12)/G12)) -> - | I12: =IF((COUNTIFS(B6:B8,">="&1,C6:C8,"="&B12))>228,228,(COUNTIFS(B6:B8,">="&1,C6:C8,"="&B12))) -> 0 | J12: =IF(I12=0,"-",(COUNTIFS(C6:C8,"="&B12,I6:I8,"<="&DATE(2024,12,31),K6:K8,">="&0)/I12)) -> - | K12: =IF(I12=0,"-",IF(J12=1,"-",(COUNTIFS(B6:B8,">"&0,C6:C8,"="&B12,I6:I8,">"&DATE(2024,12,31),K6:K8,">="&0)/(I12-COUNTIFS(B6:B8,">"&0,C6:C8,"="&B12,I6:I8,"<="&DATE(2024,12,31),K6:K8,">="&0))))) -> - | L12: =IF(I12=0,"-",G12/I12) -> -
B13: Sem Info | C13: =COUNTIFS(B6:B8,">"&0,C6:C8,"="&B13) -> 0 | D13: =COUNTIFS(B6:B8,">="&1,C6:C8,B13,K6:K8,">="&0,K6:K8,"<"&50) -> 0 | E13: =COUNTIFS(B6:B8,">="&1,C6:C8,B13,K6:K8,">="&50,K6:K8,"<"&500) -> 0 | F13: =COUNTIFS(B6:B7,">="&1,C6:C7,B13,K6:K7,">="&500) -> 0 | G13: =COUNTIFS(B6:B8,">="&1,C6:C8,B13,K6:K8,">="&0,I6:I8,">"&DATE(2021,1,1)) -> 0 | H13: =IF(G13=0,"-",(SUM(E13,F13)/G13)) -> - | I13: =IF((COUNTIFS(B6:B7,">="&1,C6:C7,"="&B13))>228,228,(COUNTIFS(B6:B7,">="&1,C6:C7,"="&B13))) -> 0 | J13: =IF(I13=0,"-",(COUNTIFS(C6:C8,"="&B13,I6:I8,"<="&DATE(2024,12,31),K6:K8,">="&0)/I13)) -> - | K13: =IF(I13=0,"-",IF(J13=1,"-",(COUNTIFS(B6:B8,">"&0,C6:C8,"="&B13,I6:I8,">"&DATE(2024,12,31),K6:K8,">="&0)/(I13-COUNTIFS(B6:B8,">"&0,C6:C8,"="&B13,I6:I8,"<="&DATE(2024,12,31),K6:K8,">="&0))))) -> - | L13: =IF(I13=0,"-",G13/I13) -> -
B14: Totais | C14: =SUM(C11:C13) -> 0 | D14: =SUM(D11:D13) -> 0 | E14: =SUM(E11:E13) -> 0 | F14: =SUM(F11:F13) -> 0 | G14: =SUM(G11:G13) -> 0 | H14: =IF(G14=0,"-",(SUM(E14,F14)/G14)) -> - | I14: =SUM(I11:I13) -> 0 | J14: =IF(I14=0,"-",(COUNTIFS(I6:I8,"<="&DATE(2024,12,31),K6:K8,">="&0)/I14)) -> - | K14: =IF(I14=0,"-",IF(J14=1,"-",(COUNTIFS(B6:B8,">"&0,I6:I8,">"&DATE(2024,12,31),K6:K8,">="&0)/(I14-COUNTIFS(B6:B8,">"&0,I6:I8,"<="&DATE(2024,12,31),K6:K8,">="&0))))) -> - | L14: =IF(I14=0,"-",G14/I14) -> -
B17: =_xlfn.CONCAT("Disjuntores com extinção de arco OMI (PVO e GVO)",TEXT(IF(SUM(I51:I53)=0," ",(SUM(G51:G53)/SUM(I51:I53))), " 0,00%")) -> Disjuntores com extinção de arco OMI (PVO e GVO)
B18: ID | C18: Sub-Família | D18: Descrição | E18: N. Série | F18: Tombamento | G18: Ano de Fabricação | H18: N. Operativo | I18: Data Análise | J18: Tipo Análise | K18: Resultado | L18: Evidência de Teste
B19: =IF(C19="","",ROW($A$1))
B20: =IF(C20="","",B19+1)
B21: =IF(C21="","",B20+1)
B22: =IF(C22="","",B21+1)
B23: =IF(C23="","",B22+1)
B24: =IF(C24="","",B23+1)
B25: =IF(C25="","",B24+1)
B26: =IF(C26="","",B25+1)
B27: =IF(C27="","",B26+1)
B28: =IF(C28="","",B27+1)
B29: =IF(C29="","",B28+1)
B30: =IF(C30="","",B29+1)
B31: =IF(C31="","",B30+1)
... B48: =IF(C48="","",B47+1)
B49: Totais
B50: Sub-Família | C50: Equipamentos | D50: Não Contaminados | E50: Contaminados | F50: PCB | G50: Testes Realizados | H50: Tx. Contaminação | I50: Meta Manual | J50: Avanço 24 | K50: Avanço 25 | L50: Avanço Meta Manual
B51: Até 1988 | C51: =COUNTIFS(B19:B48,">"&0,C19:C48,"="&B51) -> 0 | D51: =COUNTIFS(B19:B48,">="&1,C19:C48,B51,K19:K48,">="&0,K19:K48,"<"&50) -> 0 | E51: =COUNTIFS(B19:B48,">="&1,C19:C48,B51,K19:K48,">="&50,K19:K48,"<"&500) -> 0 | F51: =COUNTIFS(B19:B48,">="&1,C19:C48,B51,K19:K48,">="&500) -> 0 | G51: =COUNTIFS(B19:B48,">="&1,C19:C48,B51,K19:K48,">="&0,I19:I48,">"&DATE(2021,1,1)) -> 0 | H51: =IF(G51=0,"-",(SUM(E51,F51)/G51)) -> - | I51: =IF((COUNTIFS(B19:B48,">="&1,C19:C48,"="&B51))>228,228,(COUNTIFS(B19:B48,">="&1,C19:C48,"="&B51))) -> 0 | J51: =IF(I51=0,"-",(COUNTIFS(C19:C48,"="&B51,I19:I48,"<="&DATE(2024,12,31),K19:K48,">="&0)/I51)) -> - | K51: =IF(I51=0,"-",IF(J51=1,"-",(COUNTIFS(B19:B48,">"&0,C19:C48,"="&B51,I19:I48,">"&DATE(2024,12,31),K19:K48,">="&0)/(I51-COUNTIFS(B19:B48,">"&0,C19:C48,"="&B51,I19:I48,"<="&DATE(2024,12,31),K19:K48,">="&0))))) -> - | L51: =IF(I51=0,"-",G51/I51) -> -
B52: Após 1988 | C52: =COUNTIFS(B19:B48,">"&0,C19:C48,"="&B52) -> 0 | D52: =COUNTIFS(B19:B48,">="&1,C19:C48,B52,K19:K48,">="&0,K19:K48,"<"&50) -> 0 | E52: =COUNTIFS(B19:B48,">="&1,C19:C48,B52,K19:K48,">="&50,K19:K48,"<"&500) -> 0 | F52: =COUNTIFS(B19:B48,">="&1,C19:C48,B52,K19:K48,">="&500) -> 0 | G52: =COUNTIFS(B19:B48,">="&1,C19:C48,B52,K19:K48,">="&0,I19:I48,">"&DATE(2021,1,1)) -> 0 | H52: =IF(G52=0,"-",(SUM(E52,F52)/G52)) -> - | I52: =IF((COUNTIFS(B19:B48,">="&1,C19:C48,"="&B52))>228,228,(COUNTIFS(B19:B48,">="&1,C19:C48,"="&B52))) -> 0 | J52: =IF(I52=0,"-",(COUNTIFS(C19:C48,"="&B52,I19:I48,"<="&DATE(2024,12,31),K19:K48,">="&0)/I52)) -> - | K52: =IF(I52=0,"-",IF(J52=1,"-",(COUNTIFS(B19:B48,">"&0,C19:C48,"="&B52,I19:I48,">"&DATE(2024,12,31),K19:K48,">="&0)/(I52-COUNTIFS(B19:B48,">"&0,C19:C48,"="&B52,I19:I48,"<="&DATE(2024,12,31),K19:K48,">="&0))))) -> - | L52: =IF(I52=0,"-",G52/I52) -> -
B53: Sem Info | C53: =COUNTIFS(B19:B48,">"&0,C19:C48,"="&B53) -> 0 | D53: =COUNTIFS(B19:B48,">="&1,C19:C48,B53,K19:K48,">="&0,K19:K48,"<"&50) -> 0 | E53: =COUNTIFS(B19:B48,">="&1,C19:C48,B53,K19:K48,">="&50,K19:K48,"<"&500) -> 0 | F53: =COUNTIFS(B19:B47,">="&1,C19:C47,B53,K19:K47,">="&500) -> 0 | G53: =COUNTIFS(B19:B48,">="&1,C19:C48,B53,K19:K48,">="&0,I19:I48,">"&DATE(2021,1,1)) -> 0 | H53: =IF(G53=0,"-",(SUM(E53,F53)/G53)) -> - | I53: =IF((COUNTIFS(B19:B47,">="&1,C19:C47,"="&B53))>228,228,(COUNTIFS(B19:B47,">="&1,C19:C47,"="&B53))) -> 0 | J53: =IF(I53=0,"-",(COUNTIFS(C19:C48,"="&B53,I19:I48,"<="&DATE(2024,12,31),K19:K48,">="&0)/I53)) -> - | K53: =IF(I53=0,"-",IF(J53=1,"-",(COUNTIFS(B19:B48,">"&0,C19:C48,"="&B53,I19:I48,">"&DATE(2024,12,31),K19:K48,">="&0)/(I53-COUNTIFS(B19:B48,">"&0,C19:C48,"="&B53,I19:I48,"<="&DATE(2024,12,31),K19:K48,">="&0))))) -> - | L53: =IF(I53=0,"-",G53/I53) -> -
B54: Totais | C54: =SUM(C51:C53) -> 0 | D54: =SUM(D51:D53) -> 0 | E54: =SUM(E51:E53) -> 0 | F54: =SUM(F51:F53) -> 0 | G54: =SUM(G51:G53) -> 0 | H54: =IF(G54=0,"-",(SUM(E54,F54)/G54)) -> - | I54: =SUM(I51:I53) -> 0 | J54: =IF(I54=0,"-",(COUNTIFS(I19:I48,"<="&DATE(2024,12,31),K19:K48,">="&0)/I54)) -> - | K54: =IF(I54=0,"-",IF(J54=1,"-",(COUNTIFS(B19:B48,">"&0,I19:I48,">"&DATE(2024,12,31),K19:K48,">="&0)/(I54-COUNTIFS(B19:B48,">"&0,I19:I48,"<="&DATE(2024,12,31),K19:K48,">="&0))))) -> - | L54: =IF(I54=0,"-",G54/I54) -> -
B57: =_xlfn.CONCAT("Religadores",TEXT(IF(SUM(I83:I85)=0," ",(SUM(G83:G85)/SUM(I83:I85))), " 0,00%")) -> Religadores
B58: ID | C58: Sub-Família | D58: Descrição | E58: N. Série | F58: Tombamento | G58: Ano de Fabricação | H58: N. Operativo | I58: Data Análise | J58: Tipo Análise | K58: Resultado | L58: Evidência de Teste
B59: =IF(C59="","",ROW($A$1))
B60: =IF(C60="","",(B59+1))
B61: =IF(C61="","",(B60+1))
B62: =IF(C62="","",(B61+1))
B63: =IF(C63="","",(B62+1))
...

Sheet ESE
B1: Informações de Testes Realizados
B4: =_xlfn.CONCAT("Transformadores de Rede Subterrânea",TEXT(IF(SUM(I11:I13)=0," ",(SUM(G11:G13)/SUM(I11:I13))), " 0,00%")) -> Transformadores de Rede Subterrânea
B5: ID | C5: Sub-Família | D5: Descrição | E5: N. Série | F5: Tombamento | G5: Ano de Fabricação | H5: N. Operativo | I5: Data Análise | J5: Tipo Análise | K5: Resultado | L5: Evidência de Teste
B6: =IF(C6="","",ROW($A$1))
B7: =IF(B6="","",(B6+1))
B9: Totais
B10: Sub-Família | C10: Equipamentos | D10: Não Contaminados | E10: Contaminados | F10: PCB | G10: Testes Realizados | H10: Tx. Contaminação | I10: Meta Manual | J10: Avanço 24 | K10: Avanço 25 | L10: Avanço Meta Manual
B11: Até 1988 | C11: =COUNTIFS(B6:B8,">"&0,C6:C8,"="&B11) -> 0 | D11: =COUNTIFS(B6:B8,">="&1,C6:C8,B11,K6:K8,">="&0,K6:K8,"<"&50) -> 0 | E11: =COUNTIFS(B6:B8,">="&1,C6:C8,B11,K6:K8,">="&50,K6:K8,"<"&500) -> 0 | F11: =COUNTIFS(B6:B8,">="&1,C6:C8,B11,K6:K8,">="&500) -> 0 | G11: =COUNTIFS(B6:B8,">="&1,C6:C8,B11,K6:K8,">="&0,I6:I8,">"&DATE(2021,1,1)) -> 0 | H11: =IF(G11=0,"-",(SUM(E11,F11)/G11)) -> - | I11: =IF((COUNTIFS(B6:B8,">="&1,C6:C8,"="&B11))>228,228,(COUNTIFS(B6:B8,">="&1,C6:C8,"="&B11))) -> 0 | J11: =IF(I11=0,"-",(COUNTIFS(C6:C8,"="&B11,I6:I8,"<="&DATE(2024,12,31),K6:K8,">="&0)/I11)) -> - | K11: =IF(I11=0,"-",IF(J11=1,"-",(COUNTIFS(B6:B8,">"&0,C6:C8,"="&B11,I6:I8,">"&DATE(2024,12,31),K6:K8,">="&0)/(I11-COUNTIFS(B6:B8,">"&0,C6:C8,"="&B11,I6:I8,"<="&DATE(2024,12,31),K6:K8,">="&0))))) -> - | L11: =IF(I11=0,"-",G11/I11) -> -
B12: Após 1988 | C12: =COUNTIFS(B6:B8,">"&0,C6:C8,"="&B12) -> 0 | D12: =COUNTIFS(B6:B8,">="&1,C6:C8,B12,K6:K8,">="&0,K6:K8,"<"&50) -> 0 | E12: =COUNTIFS(B6:B8,">="&1,C6:C8,B12,K6:K8,">="&50,K6:K8,"<"&500) -> 0 | F12: =COUNTIFS(B6:B8,">="&1,C6:C8,B12,K6:K8,">="&500) -> 0 | G12: =COUNTIFS(B6:B8,">="&1,C6:C8,B12,K6:K8,">="&0,I6:I8,">"&DATE(2021,1,1)) -> 0 | H12: =IF(G12=0,"-",(SUM(E12,F12)/G12)) -> - | I12: =IF((COUNTIFS(B6:B8,">="&1,C6:C8,"="&B12))>228,228,(COUNTIFS(B6:B8,">="&1,C6:C8,"="&B12))) -> 0 | J12: =IF(I12=0,"-",(COUNTIFS(C6:C8,"="&B12,I6:I8,"<="&DATE(2024,12,31),K6:K8,">="&0)/I12)) -> - | K12: =IF(I12=0,"-",IF(J12=1,"-",(COUNTIFS(B6:B8,">"&0,C6:C8,"="&B12,I6:I8,">"&DATE(2024,12,31),K6:K8,">="&0)/(I12-COUNTIFS(B6:B8,">"&0,C6:C8,"="&B12,I6:I8,"<="&DATE(2024,12,31),K6:K8,">="&0))))) -> - | L12: =IF(I12=0,"-",G12/I12) -> -
B13: Sem Info | C13: =COUNTIFS(B6:B8,">"&0,C6:C8,"="&B13) -> 0 | D13: =COUNTIFS(B6:B8,">="&1,C6:C8,B13,K6:K8,">="&0,K6:K8,"<"&50) -> 0 | E13: =COUNTIFS(B6:B8,">="&1,C6:C8,B13,K6:K8,">="&50,K6:K8,"<"&500) -> 0 | F13: =COUNTIFS(B6:B7,">="&1,C6:C7,B13,K6:K7,">="&500) -> 0 | G13: =COUNTIFS(B6:B8,">="&1,C6:C8,B13,K6:K8,">="&0,I6:I8,">"&DATE(2021,1,1)) -> 0 | H13: =IF(G13=0,"-",(SUM(E13,F13)/G13)) -> - | I13: =IF((COUNTIFS(B6:B7,">="&1,C6:C7,"="&B13))>228,228,(COUNTIFS(B6:B7,">="&1,C6:C7,"="&B13))) -> 0 | J13: =IF(I13=0,"-",(COUNTIFS(C6:C8,"="&B13,I6:I8,"<="&DATE(2024,12,31),K6:K8,">="&0)/I13)) -> - | K13: =IF(I13=0,"-",IF(J13=1,"-",(COUNTIFS(B6:B8,">"&0,C6:C8,"="&B13,I6:I8,">"&DATE(2024,12,31),K6:K8,">="&0)/(I13-COUNTIFS(B6:B8,">"&0,C6:C8,"="&B13,I6:I8,"<="&DATE(2024,12,31),K6:K8,">="&0))))) -> - | L13: =IF(I13=0,"-",G13/I13) -> -
B14: Totais | C14: =SUM(C11:C13) -> 0 | D14: =SUM(D11:D13) -> 0 | E14: =SUM(E11:E13) -> 0 | F14: =SUM(F11:F13) -> 0 | G14: =SUM(G11:G13) -> 0 | H14: =IF(G14=0,"-",(SUM(E14,F14)/G14)) -> - | I14: =SUM(I11:I13) -> 0 | J14: =IF(I14=0,"-",(COUNTIFS(I6:I8,"<="&DATE(2024,12,31),K6:K8,">="&0)/I14)) -> - | K14: =IF(I14=0,"-",IF(J14=1,"-",(COUNTIFS(B6:B8,">"&0,I6:I8,">"&DATE(2024,12,31),K6:K8,">="&0)/(I14-COUNTIFS(B6:B8,">"&0,I6:I8,"<="&DATE(2024,12,31),K6:K8,">="&0))))) -> - | L14: =IF(I14=0,"-",G14/I14) -> -
B17: =_xlfn.CONCAT("Disjuntores com extinção de arco OMI (PVO e GVO)",TEXT(IF(SUM(I51:I53)=0," ",(SUM(G51:G53)/SUM(I51:I53))), " 0,00%")) -> Disjuntores com extinção de arco OMI (PVO e GVO)
B18: ID | C18: Sub-Família | D18: Descrição | E18: N. Série | F18: Tombamento | G18: Ano de Fabricação | H18: N. Operativo | I18: Data Análise | J18: Tipo Análise | K18: Resultado | L18: Evidência de Teste
B19: =IF(C19="","",ROW($A$1))
B20: =IF(C20="","",B19+1)
B21: =IF(C21="","",B20+1)
B22: =IF(C22="","",B21+1)
B23: =IF(C23="","",B22+1)
B24: =IF(C24="","",B23+1)
B25: =IF(C25="","",B24+1)
B26: =IF(C26="","",B25+1)
B27: =IF(C27="","",B26+1)
B28: =IF(C28="","",B27+1)
B29: =IF(C29="","",B28+1)
B30: =IF(C30="","",B29+1)
B31: =IF(C31="","",B30+1)
... B48: =IF(C48="","",B47+1)
B49: Totais
B50: Sub-Família | C50: Equipamentos | D50: Não Contaminados | E50: Contaminados | F50: PCB | G50: Testes Realizados | H50: Tx. Contaminação | I50: Meta Manual | J50: Avanço 24 | K50: Avanço 25 | L50: Avanço Meta Manual
B51: Até 1988 | C51: =COUNTIFS(B19:B48,">"&0,C19:C48,"="&B51) -> 0 | D51: =COUNTIFS(B19:B48,">="&1,C19:C48,B51,K19:K48,">="&0,K19:K48,"<"&50) -> 0 | E51: =COUNTIFS(B19:B48,">="&1,C19:C48,B51,K19:K48,">="&50,K19:K48,"<"&500) -> 0 | F51: =COUNTIFS(B19:B48,">="&1,C19:C48,B51,K19:K48,">="&500) -> 0 | G51: =COUNTIFS(B19:B48,">="&1,C19:C48,B51,K19:K48,">="&0,I19:I48,">"&DATE(2021,1,1)) -> 0 | H51: =IF(G51=0,"-",(SUM(E51,F51)/G51)) -> - | I51: =IF((COUNTIFS(B19:B48,">="&1,C19:C48,"="&B51))>228,228,(COUNTIFS(B19:B48,">="&1,C19:C48,"="&B51))) -> 0 | J51: =IF(I51=0,"-",(COUNTIFS(C19:C48,"="&B51,I19:I48,"<="&DATE(2024,12,31),K19:K48,">="&0)/I51)) -> - | K51: =IF(I51=0,"-",IF(J51=1,"-",(COUNTIFS(B19:B48,">"&0,C19:C48,"="&B51,I19:I48,">"&DATE(2024,12,31),K19:K48,">="&0)/(I51-COUNTIFS(B19:B48,">"&0,C19:C48,"="&B51,I19:I48,"<="&DATE(2024,12,31),K19:K48,">="&0))))) -> - | L51: =IF(I51=0,"-",G51/I51) -> -
B52: Após 1988 | C52: =COUNTIFS(B19:B48,">"&0,C19:C48,"="&B52) -> 0 | D52: =COUNTIFS(B19:B48,">="&1,C19:C48,B52,K19:K48,">="&0,K19:K48,"<"&50) -> 0 | E52: =COUNTIFS(B19:B48,">="&1,C19:C48,B52,K19:K48,">="&50,K19:K48,"<"&500) -> 0 | F52: =COUNTIFS(B19:B48,">="&1,C19:C48,B52,K19:K48,">="&500) -> 0 | G52: =COUNTIFS(B19:B48,">="&1,C19:C48,B52,K19:K48,">="&0,I19:I48,">"&DATE(2021,1,1)) -> 0 | H52: =IF(G52=0,"-",(SUM(E52,F52)/G52)) -> - | I52: =IF((COUNTIFS(B19:B48,">="&1,C19:C48,"="&B52))>228,228,(COUNTIFS(B19:B48,">="&1,C19:C48,"="&B52))) -> 0 | J52: =IF(I52=0,"-",(COUNTIFS(C19:C48,"="&B52,I19:I48,"<="&DATE(2024,12,31),K19:K48,">="&0)/I52)) -> - | K52: =IF(I52=0,"-",IF(J52=1,"-",(COUNTIFS(B19:B48,">"&0,C19:C48,"="&B52,I19:I48,">"&DATE(2024,12,31),K19:K48,">="&0)/(I52-COUNTIFS(B19:B48,">"&0,C19:C48,"="&B52,I19:I48,"<="&DATE(2024,12,31),K19:K48,">="&0))))) -> - | L52: =IF(I52=0,"-",G52/I52) -> -
B53: Sem Info | C53: =COUNTIFS(B19:B48,">"&0,C19:C48,"="&B53) -> 0 | D53: =COUNTIFS(B19:B48,">="&1,C19:C48,B53,K19:K48,">="&0,K19:K48,"<"&50) -> 0 | E53: =COUNTIFS(B19:B48,">="&1,C19:C48,B53,K19:K48,">="&50,K19:K48,"<"&500) -> 0 | F53: =COUNTIFS(B19:B47,">="&1,C19:C47,B53,K19:K47,">="&500) -> 0 | G53: =COUNTIFS(B19:B48,">="&1,C19:C48,B53,K19:K48,">="&0,I19:I48,">"&DATE(2021,1,1)) -> 0 | H53: =IF(G53=0,"-",(SUM(E53,F53)/G53)) -> - | I53: =IF((COUNTIFS(B19:B47,">="&1,C19:C47,"="&B53))>228,228,(COUNTIFS(B19:B47,">="&1,C19:C47,"="&B53))) -> 0 | J53: =IF(I53=0,"-",(COUNTIFS(C19:C48,"="&B53,I19:I48,"<="&DATE(2024,12,31),K19:K48,">="&0)/I53)) -> - | K53: =IF(I53=0,"-",IF(J53=1,"-",(COUNTIFS(B19:B48,">"&0,C19:C48,"="&B53,I19:I48,">"&DATE(2024,12,31),K19:K48,">="&0)/(I53-COUNTIFS(B19:B48,">"&0,C19:C48,"="&B53,I19:I48,"<="&DATE(2024,12,31),K19:K48,">="&0))))) -> - | L53: =IF(I53=0,"-",G53/I53) -> -
B54: Totais | C54: =SUM(C51:C53) -> 0 | D54: =SUM(D51:D53) -> 0 | E54: =SUM(E51:E53) -> 0 | F54: =SUM(F51:F53) -> 0 | G54: =SUM(G51:G53) -> 0 | H54: =IF(G54=0,"-",(SUM(E54,F54)/G54)) -> - | I54: =SUM(I51:I53) -> 0 | J54: =IF(I54=0,"-",(COUNTIFS(I19:I48,"<="&DATE(2024,12,31),K19:K48,">="&0)/I54)) -> - | K54: =IF(I54=0,"-",IF(J54=1,"-",(COUNTIFS(B19:B48,">"&0,I19:I48,">"&DATE(2024,12,31),K19:K48,">="&0)/(I54-COUNTIFS(B19:B48,">"&0,I19:I48,"<="&DATE(2024,12,31),K19:K48,">="&0))))) -> - | L54: =IF(I54=0,"-",G54/I54) -> -
B57: =_xlfn.CONCAT("Religadores",TEXT(IF(SUM(I83:I85)=0," ",(SUM(G83:G85)/SUM(I83:I85))), " 0,00%")) -> Religadores
B58: ID | C58: Sub-Família | D58: Descrição | E58: N. Série | F58: Tombamento | G58: Ano de Fabricação | H58: N. Operativo | I58: Data Análise | J58: Tipo Análise | K58: Resultado | L58: Evidência de Teste
B59: =IF(C59="","",ROW($A$1))
B60: =IF(C60="","",(B59+1))
B61: =IF(C61="","",(B60+1))
B62: =IF(C62="","",(B61+1))
B63: =IF(C63="","",(B62+1))
...

Sheet ESS
B1: Informações de Testes Realizados
B4: =_xlfn.CONCAT("Transformadores de Rede Subterrânea",TEXT(IF(SUM(I11:I13)=0," ",(SUM(G11:G13)/SUM(I11:I13))), " 0,00%")) -> Transformadores de Rede Subterrânea
B5: ID | C5: Sub-Família | D5: Descrição | E5: N. Série | F5: Tombamento | G5: Ano de Fabricação | H5: N. Operativo | I5: Data Análise | J5: Tipo Análise | K5: Resultado | L5: Evidência de Teste
B6: =IF(C6="","",ROW($A$1))
B7: =IF(B6="","",(B6+1))
B9: Totais
B10: Sub-Família | C10: Equipamentos | D10: Não Contaminados | E10: Contaminados | F10: PCB | G10: Testes Realizados | H10: Tx. Contaminação | I10: Meta Manual | J10: Avanço 24 | K10: Avanço 25 | L10: Avanço Meta Manual
B11: Até 1988 | C11: =COUNTIFS(B6:B8,">"&0,C6:C8,"="&B11) -> 0 | D11: =COUNTIFS(B6:B8,">="&1,C6:C8,B11,K6:K8,">="&0,K6:K8,"<"&50) -> 0 | E11: =COUNTIFS(B6:B8,">="&1,C6:C8,B11,K6:K8,">="&50,K6:K8,"<"&500) -> 0 | F11: =COUNTIFS(B6:B8,">="&1,C6:C8,B11,K6:K8,">="&500) -> 0 | G11: =COUNTIFS(B6:B8,">="&1,C6:C8,B11,K6:K8,">="&0,I6:I8,">"&DATE(2021,1,1)) -> 0 | H11: =IF(G11=0,"-",(SUM(E11,F11)/G11)) -> - | I11: =IF((COUNTIFS(B6:B8,">="&1,C6:C8,"="&B11))>228,228,(COUNTIFS(B6:B8,">="&1,C6:C8,"="&B11))) -> 0 | J11: =IF(I11=0,"-",(COUNTIFS(C6:C8,"="&B11,I6:I8,"<="&DATE(2024,12,31),K6:K8,">="&0)/I11)) -> - | K11: =IF(I11=0,"-",IF(J11=1,"-",(COUNTIFS(B6:B8,">"&0,C6:C8,"="&B11,I6:I8,">"&DATE(2024,12,31),K6:K8,">="&0)/(I11-COUNTIFS(B6:B8,">"&0,C6:C8,"="&B11,I6:I8,"<="&DATE(2024,12,31),K6:K8,">="&0))))) -> - | L11: =IF(I11=0,"-",G11/I11) -> -
B12: Após 1988 | C12: =COUNTIFS(B6:B8,">"&0,C6:C8,"="&B12) -> 0 | D12: =COUNTIFS(B6:B8,">="&1,C6:C8,B12,K6:K8,">="&0,K6:K8,"<"&50) -> 0 | E12: =COUNTIFS(B6:B8,">="&1,C6:C8,B12,K6:K8,">="&50,K6:K8,"<"&500) -> 0 | F12: =COUNTIFS(B6:B8,">="&1,C6:C8,B12,K6:K8,">="&500) -> 0 | G12: =COUNTIFS(B6:B8,">="&1,C6:C8,B12,K6:K8,">="&0,I6:I8,">"&DATE(2021,1,1)) -> 0 | H12: =IF(G12=0,"-",(SUM(E12,F12)/G12)) -> - | I12: =IF((COUNTIFS(B6:B8,">="&1,C6:C8,"="&B12))>228,228,(COUNTIFS(B6:B8,">="&1,C6:C8,"="&B12))) -> 0 | J12: =IF(I12=0,"-",(COUNTIFS(C6:C8,"="&B12,I6:I8,"<="&DATE(2024,12,31),K6:K8,">="&0)/I12)) -> - | K12: =IF(I12=0,"-",IF(J12=1,"-",(COUNTIFS(B6:B8,">"&0,C6:C8,"="&B12,I6:I8,">"&DATE(2024,12,31),K6:K8,">="&0)/(I12-COUNTIFS(B6:B8,">"&0,C6:C8,"="&B12,I6:I8,"<="&DATE(2024,12,31),K6:K8,">="&0))))) -> - | L12: =IF(I12=0,"-",G12/I12) -> -
B13: Sem Info | C13: =COUNTIFS(B6:B8,">"&0,C6:C8,"="&B13) -> 0 | D13: =COUNTIFS(B6:B8,">="&1,C6:C8,B13,K6:K8,">="&0,K6:K8,"<"&50) -> 0 | E13: =COUNTIFS(B6:B8,">="&1,C6:C8,B13,K6:K8,">="&50,K6:K8,"<"&500) -> 0 | F13: =COUNTIFS(B6:B7,">="&1,C6:C7,B13,K6:K7,">="&500) -> 0 | G13: =COUNTIFS(B6:B8,">="&1,C6:C8,B13,K6:K8,">="&0,I6:I8,">"&DATE(2021,1,1)) -> 0 | H13: =IF(G13=0,"-",(SUM(E13,F13)/G13)) -> - | I13: =IF((COUNTIFS(B6:B7,">="&1,C6:C7,"="&B13))>228,228,(COUNTIFS(B6:B7,">="&1,C6:C7,"="&B13))) -> 0 | J13: =IF(I13=0,"-",(COUNTIFS(C6:C8,"="&B13,I6:I8,"<="&DATE(2024,12,31),K6:K8,">="&0)/I13)) -> - | K13: =IF(I13=0,"-",IF(J13=1,"-",(COUNTIFS(B6:B8,">"&0,C6:C8,"="&B13,I6:I8,">"&DATE(2024,12,31),K6:K8,">="&0)/(I13-COUNTIFS(B6:B8,">"&0,C6:C8,"="&B13,I6:I8,"<="&DATE(2024,12,31),K6:K8,">="&0))))) -> - | L13: =IF(I13=0,"-",G13/I13) -> -
B14: Totais | C14: =SUM(C11:C13) -> 0 | D14: =SUM(D11:D13) -> 0 | E14: =SUM(E11:E13) -> 0 | F14: =SUM(F11:F13) -> 0 | G14: =SUM(G11:G13) -> 0 | H14: =IF(G14=0,"-",(SUM(E14,F14)/G14)) -> - | I14: =SUM(I11:I13) -> 0 | J14: =IF(I14=0,"-",(COUNTIFS(I6:I8,"<="&DATE(2024,12,31),K6:K8,">="&0)/I14)) -> - | K14: =IF(I14=0,"-",IF(J14=1,"-",(COUNTIFS(B6:B8,">"&0,I6:I8,">"&DATE(2024,12,31),K6:K8,">="&0)/(I14-COUNTIFS(B6:B8,">"&0,I6:I8,"<="&DATE(2024,12,31),K6:K8,">="&0))))) -> - | L14: =IF(I14=0,"-",G14/I14) -> -
B17: =_xlfn.CONCAT("Disjuntores com extinção de arco OMI (PVO e GVO)",TEXT(IF(SUM(I51:I53)=0," ",(SUM(G51:G53)/SUM(I51:I53))), " 0,00%")) -> Disjuntores com extinção de arco OMI (PVO e GVO)
B18: ID | C18: Sub-Família | D18: Descrição | E18: N. Série | F18: Tombamento | G18: Ano de Fabricação | H18: N. Operativo | I18: Data Análise | J18: Tipo Análise | K18: Resultado | L18: Evidência de Teste
B19: =IF(C19="","",ROW($A$1))
B20: =IF(C20="","",B19+1)
B21: =IF(C21="","",B20+1)
B22: =IF(C22="","",B21+1)
B23: =IF(C23="","",B22+1)
B24: =IF(C24="","",B23+1)
B25: =IF(C25="","",B24+1)
B26: =IF(C26="","",B25+1)
B27: =IF(C27="","",B26+1)
B28: =IF(C28="","",B27+1)
B29: =IF(C29="","",B28+1)
B30: =IF(C30="","",B29+1)
B31: =IF(C31="","",B30+1)
... B48: =IF(C48="","",B47+1)
B49: Totais
B50: Sub-Família | C50: Equipamentos | D50: Não Contaminados | E50: Contaminados | F50: PCB | G50: Testes Realizados | H50: Tx. Contaminação | I50: Meta Manual | J50: Avanço 24 | K50: Avanço 25 | L50: Avanço Meta Manual
B51: Até 1988 | C51: =COUNTIFS(B19:B48,">"&0,C19:C48,"="&B51) -> 0 | D51: =COUNTIFS(B19:B48,">="&1,C19:C48,B51,K19:K48,">="&0,K19:K48,"<"&50) -> 0 | E51: =COUNTIFS(B19:B48,">="&1,C19:C48,B51,K19:K48,">="&50,K19:K48,"<"&500) -> 0 | F51: =COUNTIFS(B19:B48,">="&1,C19:C48,B51,K19:K48,">="&500) -> 0 | G51: =COUNTIFS(B19:B48,">="&1,C19:C48,B51,K19:K48,">="&0,I19:I48,">"&DATE(2021,1,1)) -> 0 | H51: =IF(G51=0,"-",(SUM(E51,F51)/G51)) -> - | I51: =IF((COUNTIFS(B19:B48,">="&1,C19:C48,"="&B51))>228,228,(COUNTIFS(B19:B48,">="&1,C19:C48,"="&B51))) -> 0 | J51: =IF(I51=0,"-",(COUNTIFS(C19:C48,"="&B51,I19:I48,"<="&DATE(2024,12,31),K19:K48,">="&0)/I51)) -> - | K51: =IF(I51=0,"-",IF(J51=1,"-",(COUNTIFS(B19:B48,">"&0,C19:C48,"="&B51,I19:I48,">"&DATE(2024,12,31),K19:K48,">="&0)/(I51-COUNTIFS(B19:B48,">"&0,C19:C48,"="&B51,I19:I48,"<="&DATE(2024,12,31),K19:K48,">="&0))))) -> - | L51: =IF(I51=0,"-",G51/I51) -> -
B52: Após 1988 | C52: =COUNTIFS(B19:B48,">"&0,C19:C48,"="&B52) -> 0 | D52: =COUNTIFS(B19:B48,">="&1,C19:C48,B52,K19:K48,">="&0,K19:K48,"<"&50) -> 0 | E52: =COUNTIFS(B19:B48,">="&1,C19:C48,B52,K19:K48,">="&50,K19:K48,"<"&500) -> 0 | F52: =COUNTIFS(B19:B48,">="&1,C19:C48,B52,K19:K48,">="&500) -> 0 | G52: =COUNTIFS(B19:B48,">="&1,C19:C48,B52,K19:K48,">="&0,I19:I48,">"&DATE(2021,1,1)) -> 0 | H52: =IF(G52=0,"-",(SUM(E52,F52)/G52)) -> - | I52: =IF((COUNTIFS(B19:B48,">="&1,C19:C48,"="&B52))>228,228,(COUNTIFS(B19:B48,">="&1,C19:C48,"="&B52))) -> 0 | J52: =IF(I52=0,"-",(COUNTIFS(C19:C48,"="&B52,I19:I48,"<="&DATE(2024,12,31),K19:K48,">="&0)/I52)) -> - | K52: =IF(I52=0,"-",IF(J52=1,"-",(COUNTIFS(B19:B48,">"&0,C19:C48,"="&B52,I19:I48,">"&DATE(2024,12,31),K19:K48,">="&0)/(I52-COUNTIFS(B19:B48,">"&0,C19:C48,"="&B52,I19:I48,"<="&DATE(2024,12,31),K19:K48,">="&0))))) -> - | L52: =IF(I52=0,"-",G52/I52) -> -
B53: Sem Info | C53: =COUNTIFS(B19:B48,">"&0,C19:C48,"="&B53) -> 0 | D53: =COUNTIFS(B19:B48,">="&1,C19:C48,B53,K19:K48,">="&0,K19:K48,"<"&50) -> 0 | E53: =COUNTIFS(B19:B48,">="&1,C19:C48,B53,K19:K48,">="&50,K19:K48,"<"&500) -> 0 | F53: =COUNTIFS(B19:B47,">="&1,C19:C47,B53,K19:K47,">="&500) -> 0 | G53: =COUNTIFS(B19:B48,">="&1,C19:C48,B53,K19:K48,">="&0,I19:I48,">"&DATE(2021,1,1)) -> 0 | H53: =IF(G53=0,"-",(SUM(E53,F53)/G53)) -> - | I53: =IF((COUNTIFS(B19:B47,">="&1,C19:C47,"="&B53))>228,228,(COUNTIFS(B19:B47,">="&1,C19:C47,"="&B53))) -> 0 | J53: =IF(I53=0,"-",(COUNTIFS(C19:C48,"="&B53,I19:I48,"<="&DATE(2024,12,31),K19:K48,">="&0)/I53)) -> - | K53: =IF(I53=0,"-",IF(J53=1,"-",(COUNTIFS(B19:B48,">"&0,C19:C48,"="&B53,I19:I48,">"&DATE(2024,12,31),K19:K48,">="&0)/(I53-COUNTIFS(B19:B48,">"&0,C19:C48,"="&B53,I19:I48,"<="&DATE(2024,12,31),K19:K48,">="&0))))) -> - | L53: =IF(I53=0,"-",G53/I53) -> -
